[rospy.client][INFO] 2021-02-12 16:31:13,913: init_node, name[/solution], pid[3835]
[xmlrpc][INFO] 2021-02-12 16:31:13,914: XML-RPC server binding to 0.0.0.0:0
[xmlrpc][INFO] 2021-02-12 16:31:13,919: Started XML-RPC server [http://ip-172-31-17-9:39777/]
[rospy.init][INFO] 2021-02-12 16:31:13,919: ROS Slave URI: [http://ip-172-31-17-9:39777/]
[rospy.impl.masterslave][INFO] 2021-02-12 16:31:13,922: _ready: http://ip-172-31-17-9:39777/
[xmlrpc][INFO] 2021-02-12 16:31:13,930: xml rpc node: starting XML-RPC server
[rospy.registration][INFO] 2021-02-12 16:31:13,930: Registering with master node http://localhost:40963
[rospy.init][INFO] 2021-02-12 16:31:14,026: registered with master
[rospy.rosout][INFO] 2021-02-12 16:31:14,032: initializing /rosout core topic
[rospy.rosout][INFO] 2021-02-12 16:31:14,040: connected to core topic /rosout
[rospy.simtime][INFO] 2021-02-12 16:31:14,047: /use_sim_time is not set, will not subscribe to simulated time [/clock] topic
[rospy.internal][INFO] 2021-02-12 16:31:14,106: topic[/two_ints] adding connection to [http://ip-172-31-17-9:43152/], count 0
[rospy.internal][INFO] 2021-02-12 16:31:14,264: topic[/rosout] adding connection to [/rosout], count 0
[rosout][ERROR] 2021-02-12 16:31:14,857: bad callback: <function callback at 0x7f04a2b905f0>
Traceback (most recent call last):
  File "/opt/ros/kinetic/lib/python2.7/dist-packages/rospy/topics.py", line 750, in _invoke_callback
    cb(msg)
  File "/mnt/data2/students/sub1/ccc_v1_w_OIyD_190740/asn329241_1/asn329242_1/work/catkin_ws/src/project1_solution/scripts/solution.py", line 8, in callback
    rospy.loginfo(rospy.get_caller_id() + "I heard %s", data.data)
AttributeError: 'TwoInts' object has no attribute 'data'

[rosout][ERROR] 2021-02-12 16:31:16,855: bad callback: <function callback at 0x7f04a2b905f0>
Traceback (most recent call last):
  File "/opt/ros/kinetic/lib/python2.7/dist-packages/rospy/topics.py", line 750, in _invoke_callback
    cb(msg)
  File "/mnt/data2/students/sub1/ccc_v1_w_OIyD_190740/asn329241_1/asn329242_1/work/catkin_ws/src/project1_solution/scripts/solution.py", line 8, in callback
    rospy.loginfo(rospy.get_caller_id() + "I heard %s", data.data)
AttributeError: 'TwoInts' object has no attribute 'data'

[rosout][ERROR] 2021-02-12 16:31:18,854: bad callback: <function callback at 0x7f04a2b905f0>
Traceback (most recent call last):
  File "/opt/ros/kinetic/lib/python2.7/dist-packages/rospy/topics.py", line 750, in _invoke_callback
    cb(msg)
  File "/mnt/data2/students/sub1/ccc_v1_w_OIyD_190740/asn329241_1/asn329242_1/work/catkin_ws/src/project1_solution/scripts/solution.py", line 8, in callback
    rospy.loginfo(rospy.get_caller_id() + "I heard %s", data.data)
AttributeError: 'TwoInts' object has no attribute 'data'

[rosout][ERROR] 2021-02-12 16:31:20,855: bad callback: <function callback at 0x7f04a2b905f0>
Traceback (most recent call last):
  File "/opt/ros/kinetic/lib/python2.7/dist-packages/rospy/topics.py", line 750, in _invoke_callback
    cb(msg)
  File "/mnt/data2/students/sub1/ccc_v1_w_OIyD_190740/asn329241_1/asn329242_1/work/catkin_ws/src/project1_solution/scripts/solution.py", line 8, in callback
    rospy.loginfo(rospy.get_caller_id() + "I heard %s", data.data)
AttributeError: 'TwoInts' object has no attribute 'data'

[rosout][ERROR] 2021-02-12 16:31:22,855: bad callback: <function callback at 0x7f04a2b905f0>
Traceback (most recent call last):
  File "/opt/ros/kinetic/lib/python2.7/dist-packages/rospy/topics.py", line 750, in _invoke_callback
    cb(msg)
  File "/mnt/data2/students/sub1/ccc_v1_w_OIyD_190740/asn329241_1/asn329242_1/work/catkin_ws/src/project1_solution/scripts/solution.py", line 8, in callback
    rospy.loginfo(rospy.get_caller_id() + "I heard %s", data.data)
AttributeError: 'TwoInts' object has no attribute 'data'

[rosout][ERROR] 2021-02-12 16:31:24,854: bad callback: <function callback at 0x7f04a2b905f0>
Traceback (most recent call last):
  File "/opt/ros/kinetic/lib/python2.7/dist-packages/rospy/topics.py", line 750, in _invoke_callback
    cb(msg)
  File "/mnt/data2/students/sub1/ccc_v1_w_OIyD_190740/asn329241_1/asn329242_1/work/catkin_ws/src/project1_solution/scripts/solution.py", line 8, in callback
    rospy.loginfo(rospy.get_caller_id() + "I heard %s", data.data)
AttributeError: 'TwoInts' object has no attribute 'data'

[rosout][ERROR] 2021-02-12 16:31:26,856: bad callback: <function callback at 0x7f04a2b905f0>
Traceback (most recent call last):
  File "/opt/ros/kinetic/lib/python2.7/dist-packages/rospy/topics.py", line 750, in _invoke_callback
    cb(msg)
  File "/mnt/data2/students/sub1/ccc_v1_w_OIyD_190740/asn329241_1/asn329242_1/work/catkin_ws/src/project1_solution/scripts/solution.py", line 8, in callback
    rospy.loginfo(rospy.get_caller_id() + "I heard %s", data.data)
AttributeError: 'TwoInts' object has no attribute 'data'

[rosout][ERROR] 2021-02-12 16:31:28,855: bad callback: <function callback at 0x7f04a2b905f0>
Traceback (most recent call last):
  File "/opt/ros/kinetic/lib/python2.7/dist-packages/rospy/topics.py", line 750, in _invoke_callback
    cb(msg)
  File "/mnt/data2/students/sub1/ccc_v1_w_OIyD_190740/asn329241_1/asn329242_1/work/catkin_ws/src/project1_solution/scripts/solution.py", line 8, in callback
    rospy.loginfo(rospy.get_caller_id() + "I heard %s", data.data)
AttributeError: 'TwoInts' object has no attribute 'data'

[rosout][ERROR] 2021-02-12 16:31:30,854: bad callback: <function callback at 0x7f04a2b905f0>
Traceback (most recent call last):
  File "/opt/ros/kinetic/lib/python2.7/dist-packages/rospy/topics.py", line 750, in _invoke_callback
    cb(msg)
  File "/mnt/data2/students/sub1/ccc_v1_w_OIyD_190740/asn329241_1/asn329242_1/work/catkin_ws/src/project1_solution/scripts/solution.py", line 8, in callback
    rospy.loginfo(rospy.get_caller_id() + "I heard %s", data.data)
AttributeError: 'TwoInts' object has no attribute 'data'

[rosout][ERROR] 2021-02-12 16:31:32,856: bad callback: <function callback at 0x7f04a2b905f0>
Traceback (most recent call last):
  File "/opt/ros/kinetic/lib/python2.7/dist-packages/rospy/topics.py", line 750, in _invoke_callback
    cb(msg)
  File "/mnt/data2/students/sub1/ccc_v1_w_OIyD_190740/asn329241_1/asn329242_1/work/catkin_ws/src/project1_solution/scripts/solution.py", line 8, in callback
    rospy.loginfo(rospy.get_caller_id() + "I heard %s", data.data)
AttributeError: 'TwoInts' object has no attribute 'data'

[rospy.core][INFO] 2021-02-12 16:31:33,639: signal_shutdown [signal-2]
[rospy.internal][INFO] 2021-02-12 16:31:33,671: topic[/rosout] removing connection to /rosout
[rospy.internal][INFO] 2021-02-12 16:31:33,675: topic[/two_ints] removing connection to http://ip-172-31-17-9:43152/
[rospy.internal][WARNING] 2021-02-12 16:31:33,677: Unknown error initiating TCP/IP socket to ip-172-31-17-9:46199 (http://ip-172-31-17-9:43152/): Traceback (most recent call last):
  File "/opt/ros/kinetic/lib/python2.7/dist-packages/rospy/impl/tcpros_base.py", line 558, in connect
    self.local_endpoint = self.socket.getsockname()
AttributeError: 'NoneType' object has no attribute 'getsockname'

[rospy.impl.masterslave][INFO] 2021-02-12 16:31:33,679: signal-2
[rospy.core][INFO] 2021-02-12 16:31:34,255: signal_shutdown [atexit]
[rospy.client][INFO] 2021-02-12 16:34:44,081: init_node, name[/solution], pid[10339]
[xmlrpc][INFO] 2021-02-12 16:34:44,081: XML-RPC server binding to 0.0.0.0:0
[xmlrpc][INFO] 2021-02-12 16:34:44,086: Started XML-RPC server [http://ip-172-31-17-9:33883/]
[rospy.impl.masterslave][INFO] 2021-02-12 16:34:44,090: _ready: http://ip-172-31-17-9:33883/
[rospy.init][INFO] 2021-02-12 16:34:44,086: ROS Slave URI: [http://ip-172-31-17-9:33883/]
[xmlrpc][INFO] 2021-02-12 16:34:44,094: xml rpc node: starting XML-RPC server
[rospy.registration][INFO] 2021-02-12 16:34:44,094: Registering with master node http://localhost:40963
[rospy.init][INFO] 2021-02-12 16:34:44,197: registered with master
[rospy.rosout][INFO] 2021-02-12 16:34:44,201: initializing /rosout core topic
[rospy.rosout][INFO] 2021-02-12 16:34:44,208: connected to core topic /rosout
[rospy.simtime][INFO] 2021-02-12 16:34:44,215: /use_sim_time is not set, will not subscribe to simulated time [/clock] topic
[rospy.internal][INFO] 2021-02-12 16:34:44,270: topic[/two_ints] adding connection to [http://ip-172-31-17-9:43152/], count 0
[rospy.internal][INFO] 2021-02-12 16:34:44,442: topic[/rosout] adding connection to [/rosout], count 0
[rosout][INFO] 2021-02-12 16:34:44,855: /solution
[rosout][INFO] 2021-02-12 16:34:46,854: /solution
[rosout][INFO] 2021-02-12 16:34:48,854: /solution
[rosout][INFO] 2021-02-12 16:34:50,854: /solution
[rosout][INFO] 2021-02-12 16:34:52,854: /solution
[rosout][INFO] 2021-02-12 16:34:54,855: /solution
[rospy.core][INFO] 2021-02-12 16:34:56,748: signal_shutdown [signal-2]
[rospy.internal][INFO] 2021-02-12 16:34:56,767: topic[/rosout] removing connection to /rosout
[rospy.internal][INFO] 2021-02-12 16:34:56,771: topic[/two_ints] removing connection to http://ip-172-31-17-9:43152/
[rospy.internal][WARNING] 2021-02-12 16:34:56,772: Unknown error initiating TCP/IP socket to ip-172-31-17-9:46199 (http://ip-172-31-17-9:43152/): Traceback (most recent call last):
  File "/opt/ros/kinetic/lib/python2.7/dist-packages/rospy/impl/tcpros_base.py", line 557, in connect
    self.read_header()
  File "/opt/ros/kinetic/lib/python2.7/dist-packages/rospy/impl/tcpros_base.py", line 650, in read_header
    self._validate_header(read_ros_handshake_header(sock, self.read_buff, self.protocol.buff_size))
AttributeError: 'NoneType' object has no attribute 'buff_size'

[rospy.topics][ERROR] 2021-02-12 16:34:56,775: Traceback (most recent call last):
  File "/opt/ros/kinetic/lib/python2.7/dist-packages/rospy/topics.py", line 326, in close
    c.close()
  File "/opt/ros/kinetic/lib/python2.7/dist-packages/rospy/impl/tcpros_base.py", line 838, in close
    self.socket.close()
AttributeError: 'NoneType' object has no attribute 'close'

[rospy.impl.masterslave][INFO] 2021-02-12 16:34:56,782: signal-2
[rospy.core][INFO] 2021-02-12 16:34:56,885: signal_shutdown [atexit]
[rospy.client][INFO] 2021-02-12 16:36:06,778: init_node, name[/solution], pid[14540]
[xmlrpc][INFO] 2021-02-12 16:36:06,779: XML-RPC server binding to 0.0.0.0:0
[xmlrpc][INFO] 2021-02-12 16:36:06,790: Started XML-RPC server [http://ip-172-31-17-9:43228/]
[rospy.init][INFO] 2021-02-12 16:36:06,790: ROS Slave URI: [http://ip-172-31-17-9:43228/]
[rospy.impl.masterslave][INFO] 2021-02-12 16:36:06,794: _ready: http://ip-172-31-17-9:43228/
[xmlrpc][INFO] 2021-02-12 16:36:06,804: xml rpc node: starting XML-RPC server
[rospy.registration][INFO] 2021-02-12 16:36:06,804: Registering with master node http://localhost:40963
[rospy.init][INFO] 2021-02-12 16:36:06,899: registered with master
[rospy.rosout][INFO] 2021-02-12 16:36:06,903: initializing /rosout core topic
[rospy.rosout][INFO] 2021-02-12 16:36:06,916: connected to core topic /rosout
[rospy.simtime][INFO] 2021-02-12 16:36:06,931: /use_sim_time is not set, will not subscribe to simulated time [/clock] topic
[rospy.internal][INFO] 2021-02-12 16:36:07,077: topic[/two_ints] adding connection to [http://ip-172-31-17-9:43152/], count 0
[rospy.internal][INFO] 2021-02-12 16:36:07,165: topic[/rosout] adding connection to [/rosout], count 0
[rosout][INFO] 2021-02-12 16:36:08,855: a: 10
b: 8
[rosout][INFO] 2021-02-12 16:36:10,856: a: 13
b: 19
[rosout][INFO] 2021-02-12 16:36:12,854: a: 13
b: 10
[rosout][INFO] 2021-02-12 16:36:14,854: a: 19
b: 12
[rosout][INFO] 2021-02-12 16:36:16,856: a: 13
b: 19
[rosout][INFO] 2021-02-12 16:36:18,855: a: 6
b: 4
[rosout][INFO] 2021-02-12 16:36:20,855: a: 4
b: 7
[rospy.core][INFO] 2021-02-12 16:36:21,543: signal_shutdown [signal-2]
[rospy.internal][INFO] 2021-02-12 16:36:21,563: topic[/rosout] removing connection to /rosout
[rospy.internal][INFO] 2021-02-12 16:36:21,568: topic[/two_ints] removing connection to http://ip-172-31-17-9:43152/
[rospy.impl.masterslave][INFO] 2021-02-12 16:36:21,572: signal-2
[rospy.internal][WARNING] 2021-02-12 16:36:21,569: Unknown error initiating TCP/IP socket to ip-172-31-17-9:46199 (http://ip-172-31-17-9:43152/): Traceback (most recent call last):
  File "/opt/ros/kinetic/lib/python2.7/dist-packages/rospy/impl/tcpros_base.py", line 558, in connect
    self.local_endpoint = self.socket.getsockname()
AttributeError: 'NoneType' object has no attribute 'getsockname'

[rospy.core][INFO] 2021-02-12 16:36:21,683: signal_shutdown [atexit]
[rospy.client][INFO] 2021-02-12 16:36:37,838: init_node, name[/solution], pid[15310]
[xmlrpc][INFO] 2021-02-12 16:36:37,838: XML-RPC server binding to 0.0.0.0:0
[xmlrpc][INFO] 2021-02-12 16:36:37,843: Started XML-RPC server [http://ip-172-31-17-9:46630/]
[rospy.init][INFO] 2021-02-12 16:36:37,843: ROS Slave URI: [http://ip-172-31-17-9:46630/]
[rospy.impl.masterslave][INFO] 2021-02-12 16:36:37,846: _ready: http://ip-172-31-17-9:46630/
[rospy.registration][INFO] 2021-02-12 16:36:37,855: Registering with master node http://localhost:40963
[xmlrpc][INFO] 2021-02-12 16:36:37,855: xml rpc node: starting XML-RPC server
[rospy.init][INFO] 2021-02-12 16:36:37,950: registered with master
[rospy.rosout][INFO] 2021-02-12 16:36:37,955: initializing /rosout core topic
[rospy.rosout][INFO] 2021-02-12 16:36:37,964: connected to core topic /rosout
[rospy.simtime][INFO] 2021-02-12 16:36:37,970: /use_sim_time is not set, will not subscribe to simulated time [/clock] topic
[rospy.internal][INFO] 2021-02-12 16:36:38,024: topic[/two_ints] adding connection to [http://ip-172-31-17-9:43152/], count 0
[rospy.internal][INFO] 2021-02-12 16:36:38,223: topic[/rosout] adding connection to [/rosout], count 0
[rosout][ERROR] 2021-02-12 16:36:38,858: bad callback: <function callback at 0x7f5e2807c5f0>
Traceback (most recent call last):
  File "/opt/ros/kinetic/lib/python2.7/dist-packages/rospy/topics.py", line 750, in _invoke_callback
    cb(msg)
  File "/mnt/data2/students/sub1/ccc_v1_w_OIyD_190740/asn329241_1/asn329242_1/work/catkin_ws/src/project1_solution/scripts/solution.py", line 8, in callback
    rospy.loginfo(data.a, data.b)
  File "/usr/lib/python2.7/logging/__init__.py", line 1167, in info
    self._log(INFO, msg, args, **kwargs)
  File "/usr/lib/python2.7/logging/__init__.py", line 1286, in _log
    self.handle(record)
  File "/usr/lib/python2.7/logging/__init__.py", line 1296, in handle
    self.callHandlers(record)
  File "/usr/lib/python2.7/logging/__init__.py", line 1336, in callHandlers
    hdlr.handle(record)
  File "/usr/lib/python2.7/logging/__init__.py", line 759, in handle
    self.emit(record)
  File "/opt/ros/kinetic/lib/python2.7/dist-packages/rosgraph/roslogging.py", line 182, in emit
    record_message = _defaultFormatter.format(record)
  File "/usr/lib/python2.7/logging/__init__.py", line 465, in format
    record.message = record.getMessage()
  File "/usr/lib/python2.7/logging/__init__.py", line 329, in getMessage
    msg = msg % self.args
TypeError: not all arguments converted during string formatting

[rosout][ERROR] 2021-02-12 16:36:40,861: bad callback: <function callback at 0x7f5e2807c5f0>
Traceback (most recent call last):
  File "/opt/ros/kinetic/lib/python2.7/dist-packages/rospy/topics.py", line 750, in _invoke_callback
    cb(msg)
  File "/mnt/data2/students/sub1/ccc_v1_w_OIyD_190740/asn329241_1/asn329242_1/work/catkin_ws/src/project1_solution/scripts/solution.py", line 8, in callback
    rospy.loginfo(data.a, data.b)
  File "/usr/lib/python2.7/logging/__init__.py", line 1167, in info
    self._log(INFO, msg, args, **kwargs)
  File "/usr/lib/python2.7/logging/__init__.py", line 1286, in _log
    self.handle(record)
  File "/usr/lib/python2.7/logging/__init__.py", line 1296, in handle
    self.callHandlers(record)
  File "/usr/lib/python2.7/logging/__init__.py", line 1336, in callHandlers
    hdlr.handle(record)
  File "/usr/lib/python2.7/logging/__init__.py", line 759, in handle
    self.emit(record)
  File "/opt/ros/kinetic/lib/python2.7/dist-packages/rosgraph/roslogging.py", line 182, in emit
    record_message = _defaultFormatter.format(record)
  File "/usr/lib/python2.7/logging/__init__.py", line 465, in format
    record.message = record.getMessage()
  File "/usr/lib/python2.7/logging/__init__.py", line 329, in getMessage
    msg = msg % self.args
TypeError: not all arguments converted during string formatting

[rosout][ERROR] 2021-02-12 16:36:42,856: bad callback: <function callback at 0x7f5e2807c5f0>
Traceback (most recent call last):
  File "/opt/ros/kinetic/lib/python2.7/dist-packages/rospy/topics.py", line 750, in _invoke_callback
    cb(msg)
  File "/mnt/data2/students/sub1/ccc_v1_w_OIyD_190740/asn329241_1/asn329242_1/work/catkin_ws/src/project1_solution/scripts/solution.py", line 8, in callback
    rospy.loginfo(data.a, data.b)
  File "/usr/lib/python2.7/logging/__init__.py", line 1167, in info
    self._log(INFO, msg, args, **kwargs)
  File "/usr/lib/python2.7/logging/__init__.py", line 1286, in _log
    self.handle(record)
  File "/usr/lib/python2.7/logging/__init__.py", line 1296, in handle
    self.callHandlers(record)
  File "/usr/lib/python2.7/logging/__init__.py", line 1336, in callHandlers
    hdlr.handle(record)
  File "/usr/lib/python2.7/logging/__init__.py", line 759, in handle
    self.emit(record)
  File "/opt/ros/kinetic/lib/python2.7/dist-packages/rosgraph/roslogging.py", line 182, in emit
    record_message = _defaultFormatter.format(record)
  File "/usr/lib/python2.7/logging/__init__.py", line 465, in format
    record.message = record.getMessage()
  File "/usr/lib/python2.7/logging/__init__.py", line 329, in getMessage
    msg = msg % self.args
TypeError: not all arguments converted during string formatting

[rosout][ERROR] 2021-02-12 16:36:44,854: bad callback: <function callback at 0x7f5e2807c5f0>
Traceback (most recent call last):
  File "/opt/ros/kinetic/lib/python2.7/dist-packages/rospy/topics.py", line 750, in _invoke_callback
    cb(msg)
  File "/mnt/data2/students/sub1/ccc_v1_w_OIyD_190740/asn329241_1/asn329242_1/work/catkin_ws/src/project1_solution/scripts/solution.py", line 8, in callback
    rospy.loginfo(data.a, data.b)
  File "/usr/lib/python2.7/logging/__init__.py", line 1167, in info
    self._log(INFO, msg, args, **kwargs)
  File "/usr/lib/python2.7/logging/__init__.py", line 1286, in _log
    self.handle(record)
  File "/usr/lib/python2.7/logging/__init__.py", line 1296, in handle
    self.callHandlers(record)
  File "/usr/lib/python2.7/logging/__init__.py", line 1336, in callHandlers
    hdlr.handle(record)
  File "/usr/lib/python2.7/logging/__init__.py", line 759, in handle
    self.emit(record)
  File "/opt/ros/kinetic/lib/python2.7/dist-packages/rosgraph/roslogging.py", line 182, in emit
    record_message = _defaultFormatter.format(record)
  File "/usr/lib/python2.7/logging/__init__.py", line 465, in format
    record.message = record.getMessage()
  File "/usr/lib/python2.7/logging/__init__.py", line 329, in getMessage
    msg = msg % self.args
TypeError: not all arguments converted during string formatting

[rosout][ERROR] 2021-02-12 16:36:46,855: bad callback: <function callback at 0x7f5e2807c5f0>
Traceback (most recent call last):
  File "/opt/ros/kinetic/lib/python2.7/dist-packages/rospy/topics.py", line 750, in _invoke_callback
    cb(msg)
  File "/mnt/data2/students/sub1/ccc_v1_w_OIyD_190740/asn329241_1/asn329242_1/work/catkin_ws/src/project1_solution/scripts/solution.py", line 8, in callback
    rospy.loginfo(data.a, data.b)
  File "/usr/lib/python2.7/logging/__init__.py", line 1167, in info
    self._log(INFO, msg, args, **kwargs)
  File "/usr/lib/python2.7/logging/__init__.py", line 1286, in _log
    self.handle(record)
  File "/usr/lib/python2.7/logging/__init__.py", line 1296, in handle
    self.callHandlers(record)
  File "/usr/lib/python2.7/logging/__init__.py", line 1336, in callHandlers
    hdlr.handle(record)
  File "/usr/lib/python2.7/logging/__init__.py", line 759, in handle
    self.emit(record)
  File "/opt/ros/kinetic/lib/python2.7/dist-packages/rosgraph/roslogging.py", line 182, in emit
    record_message = _defaultFormatter.format(record)
  File "/usr/lib/python2.7/logging/__init__.py", line 465, in format
    record.message = record.getMessage()
  File "/usr/lib/python2.7/logging/__init__.py", line 329, in getMessage
    msg = msg % self.args
TypeError: not all arguments converted during string formatting

[rosout][ERROR] 2021-02-12 16:36:48,855: bad callback: <function callback at 0x7f5e2807c5f0>
Traceback (most recent call last):
  File "/opt/ros/kinetic/lib/python2.7/dist-packages/rospy/topics.py", line 750, in _invoke_callback
    cb(msg)
  File "/mnt/data2/students/sub1/ccc_v1_w_OIyD_190740/asn329241_1/asn329242_1/work/catkin_ws/src/project1_solution/scripts/solution.py", line 8, in callback
    rospy.loginfo(data.a, data.b)
  File "/usr/lib/python2.7/logging/__init__.py", line 1167, in info
    self._log(INFO, msg, args, **kwargs)
  File "/usr/lib/python2.7/logging/__init__.py", line 1286, in _log
    self.handle(record)
  File "/usr/lib/python2.7/logging/__init__.py", line 1296, in handle
    self.callHandlers(record)
  File "/usr/lib/python2.7/logging/__init__.py", line 1336, in callHandlers
    hdlr.handle(record)
  File "/usr/lib/python2.7/logging/__init__.py", line 759, in handle
    self.emit(record)
  File "/opt/ros/kinetic/lib/python2.7/dist-packages/rosgraph/roslogging.py", line 182, in emit
    record_message = _defaultFormatter.format(record)
  File "/usr/lib/python2.7/logging/__init__.py", line 465, in format
    record.message = record.getMessage()
  File "/usr/lib/python2.7/logging/__init__.py", line 329, in getMessage
    msg = msg % self.args
TypeError: not all arguments converted during string formatting

[rosout][ERROR] 2021-02-12 16:36:50,856: bad callback: <function callback at 0x7f5e2807c5f0>
Traceback (most recent call last):
  File "/opt/ros/kinetic/lib/python2.7/dist-packages/rospy/topics.py", line 750, in _invoke_callback
    cb(msg)
  File "/mnt/data2/students/sub1/ccc_v1_w_OIyD_190740/asn329241_1/asn329242_1/work/catkin_ws/src/project1_solution/scripts/solution.py", line 8, in callback
    rospy.loginfo(data.a, data.b)
  File "/usr/lib/python2.7/logging/__init__.py", line 1167, in info
    self._log(INFO, msg, args, **kwargs)
  File "/usr/lib/python2.7/logging/__init__.py", line 1286, in _log
    self.handle(record)
  File "/usr/lib/python2.7/logging/__init__.py", line 1296, in handle
    self.callHandlers(record)
  File "/usr/lib/python2.7/logging/__init__.py", line 1336, in callHandlers
    hdlr.handle(record)
  File "/usr/lib/python2.7/logging/__init__.py", line 759, in handle
    self.emit(record)
  File "/opt/ros/kinetic/lib/python2.7/dist-packages/rosgraph/roslogging.py", line 182, in emit
    record_message = _defaultFormatter.format(record)
  File "/usr/lib/python2.7/logging/__init__.py", line 465, in format
    record.message = record.getMessage()
  File "/usr/lib/python2.7/logging/__init__.py", line 329, in getMessage
    msg = msg % self.args
TypeError: not all arguments converted during string formatting

[rosout][ERROR] 2021-02-12 16:36:52,856: bad callback: <function callback at 0x7f5e2807c5f0>
Traceback (most recent call last):
  File "/opt/ros/kinetic/lib/python2.7/dist-packages/rospy/topics.py", line 750, in _invoke_callback
    cb(msg)
  File "/mnt/data2/students/sub1/ccc_v1_w_OIyD_190740/asn329241_1/asn329242_1/work/catkin_ws/src/project1_solution/scripts/solution.py", line 8, in callback
    rospy.loginfo(data.a, data.b)
  File "/usr/lib/python2.7/logging/__init__.py", line 1167, in info
    self._log(INFO, msg, args, **kwargs)
  File "/usr/lib/python2.7/logging/__init__.py", line 1286, in _log
    self.handle(record)
  File "/usr/lib/python2.7/logging/__init__.py", line 1296, in handle
    self.callHandlers(record)
  File "/usr/lib/python2.7/logging/__init__.py", line 1336, in callHandlers
    hdlr.handle(record)
  File "/usr/lib/python2.7/logging/__init__.py", line 759, in handle
    self.emit(record)
  File "/opt/ros/kinetic/lib/python2.7/dist-packages/rosgraph/roslogging.py", line 182, in emit
    record_message = _defaultFormatter.format(record)
  File "/usr/lib/python2.7/logging/__init__.py", line 465, in format
    record.message = record.getMessage()
  File "/usr/lib/python2.7/logging/__init__.py", line 329, in getMessage
    msg = msg % self.args
TypeError: not all arguments converted during string formatting

[rosout][ERROR] 2021-02-12 16:36:54,854: bad callback: <function callback at 0x7f5e2807c5f0>
Traceback (most recent call last):
  File "/opt/ros/kinetic/lib/python2.7/dist-packages/rospy/topics.py", line 750, in _invoke_callback
    cb(msg)
  File "/mnt/data2/students/sub1/ccc_v1_w_OIyD_190740/asn329241_1/asn329242_1/work/catkin_ws/src/project1_solution/scripts/solution.py", line 8, in callback
    rospy.loginfo(data.a, data.b)
  File "/usr/lib/python2.7/logging/__init__.py", line 1167, in info
    self._log(INFO, msg, args, **kwargs)
  File "/usr/lib/python2.7/logging/__init__.py", line 1286, in _log
    self.handle(record)
  File "/usr/lib/python2.7/logging/__init__.py", line 1296, in handle
    self.callHandlers(record)
  File "/usr/lib/python2.7/logging/__init__.py", line 1336, in callHandlers
    hdlr.handle(record)
  File "/usr/lib/python2.7/logging/__init__.py", line 759, in handle
    self.emit(record)
  File "/opt/ros/kinetic/lib/python2.7/dist-packages/rosgraph/roslogging.py", line 182, in emit
    record_message = _defaultFormatter.format(record)
  File "/usr/lib/python2.7/logging/__init__.py", line 465, in format
    record.message = record.getMessage()
  File "/usr/lib/python2.7/logging/__init__.py", line 329, in getMessage
    msg = msg % self.args
TypeError: not all arguments converted during string formatting

[rosout][ERROR] 2021-02-12 16:36:56,856: bad callback: <function callback at 0x7f5e2807c5f0>
Traceback (most recent call last):
  File "/opt/ros/kinetic/lib/python2.7/dist-packages/rospy/topics.py", line 750, in _invoke_callback
    cb(msg)
  File "/mnt/data2/students/sub1/ccc_v1_w_OIyD_190740/asn329241_1/asn329242_1/work/catkin_ws/src/project1_solution/scripts/solution.py", line 8, in callback
    rospy.loginfo(data.a, data.b)
  File "/usr/lib/python2.7/logging/__init__.py", line 1167, in info
    self._log(INFO, msg, args, **kwargs)
  File "/usr/lib/python2.7/logging/__init__.py", line 1286, in _log
    self.handle(record)
  File "/usr/lib/python2.7/logging/__init__.py", line 1296, in handle
    self.callHandlers(record)
  File "/usr/lib/python2.7/logging/__init__.py", line 1336, in callHandlers
    hdlr.handle(record)
  File "/usr/lib/python2.7/logging/__init__.py", line 759, in handle
    self.emit(record)
  File "/opt/ros/kinetic/lib/python2.7/dist-packages/rosgraph/roslogging.py", line 182, in emit
    record_message = _defaultFormatter.format(record)
  File "/usr/lib/python2.7/logging/__init__.py", line 465, in format
    record.message = record.getMessage()
  File "/usr/lib/python2.7/logging/__init__.py", line 329, in getMessage
    msg = msg % self.args
TypeError: not all arguments converted during string formatting

[rosout][ERROR] 2021-02-12 16:36:58,855: bad callback: <function callback at 0x7f5e2807c5f0>
Traceback (most recent call last):
  File "/opt/ros/kinetic/lib/python2.7/dist-packages/rospy/topics.py", line 750, in _invoke_callback
    cb(msg)
  File "/mnt/data2/students/sub1/ccc_v1_w_OIyD_190740/asn329241_1/asn329242_1/work/catkin_ws/src/project1_solution/scripts/solution.py", line 8, in callback
    rospy.loginfo(data.a, data.b)
  File "/usr/lib/python2.7/logging/__init__.py", line 1167, in info
    self._log(INFO, msg, args, **kwargs)
  File "/usr/lib/python2.7/logging/__init__.py", line 1286, in _log
    self.handle(record)
  File "/usr/lib/python2.7/logging/__init__.py", line 1296, in handle
    self.callHandlers(record)
  File "/usr/lib/python2.7/logging/__init__.py", line 1336, in callHandlers
    hdlr.handle(record)
  File "/usr/lib/python2.7/logging/__init__.py", line 759, in handle
    self.emit(record)
  File "/opt/ros/kinetic/lib/python2.7/dist-packages/rosgraph/roslogging.py", line 182, in emit
    record_message = _defaultFormatter.format(record)
  File "/usr/lib/python2.7/logging/__init__.py", line 465, in format
    record.message = record.getMessage()
  File "/usr/lib/python2.7/logging/__init__.py", line 329, in getMessage
    msg = msg % self.args
TypeError: not all arguments converted during string formatting

[rosout][ERROR] 2021-02-12 16:37:00,855: bad callback: <function callback at 0x7f5e2807c5f0>
Traceback (most recent call last):
  File "/opt/ros/kinetic/lib/python2.7/dist-packages/rospy/topics.py", line 750, in _invoke_callback
    cb(msg)
  File "/mnt/data2/students/sub1/ccc_v1_w_OIyD_190740/asn329241_1/asn329242_1/work/catkin_ws/src/project1_solution/scripts/solution.py", line 8, in callback
    rospy.loginfo(data.a, data.b)
  File "/usr/lib/python2.7/logging/__init__.py", line 1167, in info
    self._log(INFO, msg, args, **kwargs)
  File "/usr/lib/python2.7/logging/__init__.py", line 1286, in _log
    self.handle(record)
  File "/usr/lib/python2.7/logging/__init__.py", line 1296, in handle
    self.callHandlers(record)
  File "/usr/lib/python2.7/logging/__init__.py", line 1336, in callHandlers
    hdlr.handle(record)
  File "/usr/lib/python2.7/logging/__init__.py", line 759, in handle
    self.emit(record)
  File "/opt/ros/kinetic/lib/python2.7/dist-packages/rosgraph/roslogging.py", line 182, in emit
    record_message = _defaultFormatter.format(record)
  File "/usr/lib/python2.7/logging/__init__.py", line 465, in format
    record.message = record.getMessage()
  File "/usr/lib/python2.7/logging/__init__.py", line 329, in getMessage
    msg = msg % self.args
TypeError: not all arguments converted during string formatting

[rosout][ERROR] 2021-02-12 16:37:02,855: bad callback: <function callback at 0x7f5e2807c5f0>
Traceback (most recent call last):
  File "/opt/ros/kinetic/lib/python2.7/dist-packages/rospy/topics.py", line 750, in _invoke_callback
    cb(msg)
  File "/mnt/data2/students/sub1/ccc_v1_w_OIyD_190740/asn329241_1/asn329242_1/work/catkin_ws/src/project1_solution/scripts/solution.py", line 8, in callback
    rospy.loginfo(data.a, data.b)
  File "/usr/lib/python2.7/logging/__init__.py", line 1167, in info
    self._log(INFO, msg, args, **kwargs)
  File "/usr/lib/python2.7/logging/__init__.py", line 1286, in _log
    self.handle(record)
  File "/usr/lib/python2.7/logging/__init__.py", line 1296, in handle
    self.callHandlers(record)
  File "/usr/lib/python2.7/logging/__init__.py", line 1336, in callHandlers
    hdlr.handle(record)
  File "/usr/lib/python2.7/logging/__init__.py", line 759, in handle
    self.emit(record)
  File "/opt/ros/kinetic/lib/python2.7/dist-packages/rosgraph/roslogging.py", line 182, in emit
    record_message = _defaultFormatter.format(record)
  File "/usr/lib/python2.7/logging/__init__.py", line 465, in format
    record.message = record.getMessage()
  File "/usr/lib/python2.7/logging/__init__.py", line 329, in getMessage
    msg = msg % self.args
TypeError: not all arguments converted during string formatting

[rosout][ERROR] 2021-02-12 16:37:04,854: bad callback: <function callback at 0x7f5e2807c5f0>
Traceback (most recent call last):
  File "/opt/ros/kinetic/lib/python2.7/dist-packages/rospy/topics.py", line 750, in _invoke_callback
    cb(msg)
  File "/mnt/data2/students/sub1/ccc_v1_w_OIyD_190740/asn329241_1/asn329242_1/work/catkin_ws/src/project1_solution/scripts/solution.py", line 8, in callback
    rospy.loginfo(data.a, data.b)
  File "/usr/lib/python2.7/logging/__init__.py", line 1167, in info
    self._log(INFO, msg, args, **kwargs)
  File "/usr/lib/python2.7/logging/__init__.py", line 1286, in _log
    self.handle(record)
  File "/usr/lib/python2.7/logging/__init__.py", line 1296, in handle
    self.callHandlers(record)
  File "/usr/lib/python2.7/logging/__init__.py", line 1336, in callHandlers
    hdlr.handle(record)
  File "/usr/lib/python2.7/logging/__init__.py", line 759, in handle
    self.emit(record)
  File "/opt/ros/kinetic/lib/python2.7/dist-packages/rosgraph/roslogging.py", line 182, in emit
    record_message = _defaultFormatter.format(record)
  File "/usr/lib/python2.7/logging/__init__.py", line 465, in format
    record.message = record.getMessage()
  File "/usr/lib/python2.7/logging/__init__.py", line 329, in getMessage
    msg = msg % self.args
TypeError: not all arguments converted during string formatting

[rosout][ERROR] 2021-02-12 16:37:06,862: bad callback: <function callback at 0x7f5e2807c5f0>
Traceback (most recent call last):
  File "/opt/ros/kinetic/lib/python2.7/dist-packages/rospy/topics.py", line 750, in _invoke_callback
    cb(msg)
  File "/mnt/data2/students/sub1/ccc_v1_w_OIyD_190740/asn329241_1/asn329242_1/work/catkin_ws/src/project1_solution/scripts/solution.py", line 8, in callback
    rospy.loginfo(data.a, data.b)
  File "/usr/lib/python2.7/logging/__init__.py", line 1167, in info
    self._log(INFO, msg, args, **kwargs)
  File "/usr/lib/python2.7/logging/__init__.py", line 1286, in _log
    self.handle(record)
  File "/usr/lib/python2.7/logging/__init__.py", line 1296, in handle
    self.callHandlers(record)
  File "/usr/lib/python2.7/logging/__init__.py", line 1336, in callHandlers
    hdlr.handle(record)
  File "/usr/lib/python2.7/logging/__init__.py", line 759, in handle
    self.emit(record)
  File "/opt/ros/kinetic/lib/python2.7/dist-packages/rosgraph/roslogging.py", line 182, in emit
    record_message = _defaultFormatter.format(record)
  File "/usr/lib/python2.7/logging/__init__.py", line 465, in format
    record.message = record.getMessage()
  File "/usr/lib/python2.7/logging/__init__.py", line 329, in getMessage
    msg = msg % self.args
TypeError: not all arguments converted during string formatting

[rosout][ERROR] 2021-02-12 16:37:08,857: bad callback: <function callback at 0x7f5e2807c5f0>
Traceback (most recent call last):
  File "/opt/ros/kinetic/lib/python2.7/dist-packages/rospy/topics.py", line 750, in _invoke_callback
    cb(msg)
  File "/mnt/data2/students/sub1/ccc_v1_w_OIyD_190740/asn329241_1/asn329242_1/work/catkin_ws/src/project1_solution/scripts/solution.py", line 8, in callback
    rospy.loginfo(data.a, data.b)
  File "/usr/lib/python2.7/logging/__init__.py", line 1167, in info
    self._log(INFO, msg, args, **kwargs)
  File "/usr/lib/python2.7/logging/__init__.py", line 1286, in _log
    self.handle(record)
  File "/usr/lib/python2.7/logging/__init__.py", line 1296, in handle
    self.callHandlers(record)
  File "/usr/lib/python2.7/logging/__init__.py", line 1336, in callHandlers
    hdlr.handle(record)
  File "/usr/lib/python2.7/logging/__init__.py", line 759, in handle
    self.emit(record)
  File "/opt/ros/kinetic/lib/python2.7/dist-packages/rosgraph/roslogging.py", line 182, in emit
    record_message = _defaultFormatter.format(record)
  File "/usr/lib/python2.7/logging/__init__.py", line 465, in format
    record.message = record.getMessage()
  File "/usr/lib/python2.7/logging/__init__.py", line 329, in getMessage
    msg = msg % self.args
TypeError: not all arguments converted during string formatting

[rosout][ERROR] 2021-02-12 16:37:10,854: bad callback: <function callback at 0x7f5e2807c5f0>
Traceback (most recent call last):
  File "/opt/ros/kinetic/lib/python2.7/dist-packages/rospy/topics.py", line 750, in _invoke_callback
    cb(msg)
  File "/mnt/data2/students/sub1/ccc_v1_w_OIyD_190740/asn329241_1/asn329242_1/work/catkin_ws/src/project1_solution/scripts/solution.py", line 8, in callback
    rospy.loginfo(data.a, data.b)
  File "/usr/lib/python2.7/logging/__init__.py", line 1167, in info
    self._log(INFO, msg, args, **kwargs)
  File "/usr/lib/python2.7/logging/__init__.py", line 1286, in _log
    self.handle(record)
  File "/usr/lib/python2.7/logging/__init__.py", line 1296, in handle
    self.callHandlers(record)
  File "/usr/lib/python2.7/logging/__init__.py", line 1336, in callHandlers
    hdlr.handle(record)
  File "/usr/lib/python2.7/logging/__init__.py", line 759, in handle
    self.emit(record)
  File "/opt/ros/kinetic/lib/python2.7/dist-packages/rosgraph/roslogging.py", line 182, in emit
    record_message = _defaultFormatter.format(record)
  File "/usr/lib/python2.7/logging/__init__.py", line 465, in format
    record.message = record.getMessage()
  File "/usr/lib/python2.7/logging/__init__.py", line 329, in getMessage
    msg = msg % self.args
TypeError: not all arguments converted during string formatting

[rosout][ERROR] 2021-02-12 16:37:12,855: bad callback: <function callback at 0x7f5e2807c5f0>
Traceback (most recent call last):
  File "/opt/ros/kinetic/lib/python2.7/dist-packages/rospy/topics.py", line 750, in _invoke_callback
    cb(msg)
  File "/mnt/data2/students/sub1/ccc_v1_w_OIyD_190740/asn329241_1/asn329242_1/work/catkin_ws/src/project1_solution/scripts/solution.py", line 8, in callback
    rospy.loginfo(data.a, data.b)
  File "/usr/lib/python2.7/logging/__init__.py", line 1167, in info
    self._log(INFO, msg, args, **kwargs)
  File "/usr/lib/python2.7/logging/__init__.py", line 1286, in _log
    self.handle(record)
  File "/usr/lib/python2.7/logging/__init__.py", line 1296, in handle
    self.callHandlers(record)
  File "/usr/lib/python2.7/logging/__init__.py", line 1336, in callHandlers
    hdlr.handle(record)
  File "/usr/lib/python2.7/logging/__init__.py", line 759, in handle
    self.emit(record)
  File "/opt/ros/kinetic/lib/python2.7/dist-packages/rosgraph/roslogging.py", line 182, in emit
    record_message = _defaultFormatter.format(record)
  File "/usr/lib/python2.7/logging/__init__.py", line 465, in format
    record.message = record.getMessage()
  File "/usr/lib/python2.7/logging/__init__.py", line 329, in getMessage
    msg = msg % self.args
TypeError: not all arguments converted during string formatting

[rosout][ERROR] 2021-02-12 16:37:14,855: bad callback: <function callback at 0x7f5e2807c5f0>
Traceback (most recent call last):
  File "/opt/ros/kinetic/lib/python2.7/dist-packages/rospy/topics.py", line 750, in _invoke_callback
    cb(msg)
  File "/mnt/data2/students/sub1/ccc_v1_w_OIyD_190740/asn329241_1/asn329242_1/work/catkin_ws/src/project1_solution/scripts/solution.py", line 8, in callback
    rospy.loginfo(data.a, data.b)
  File "/usr/lib/python2.7/logging/__init__.py", line 1167, in info
    self._log(INFO, msg, args, **kwargs)
  File "/usr/lib/python2.7/logging/__init__.py", line 1286, in _log
    self.handle(record)
  File "/usr/lib/python2.7/logging/__init__.py", line 1296, in handle
    self.callHandlers(record)
  File "/usr/lib/python2.7/logging/__init__.py", line 1336, in callHandlers
    hdlr.handle(record)
  File "/usr/lib/python2.7/logging/__init__.py", line 759, in handle
    self.emit(record)
  File "/opt/ros/kinetic/lib/python2.7/dist-packages/rosgraph/roslogging.py", line 182, in emit
    record_message = _defaultFormatter.format(record)
  File "/usr/lib/python2.7/logging/__init__.py", line 465, in format
    record.message = record.getMessage()
  File "/usr/lib/python2.7/logging/__init__.py", line 329, in getMessage
    msg = msg % self.args
TypeError: not all arguments converted during string formatting

[rosout][ERROR] 2021-02-12 16:37:16,854: bad callback: <function callback at 0x7f5e2807c5f0>
Traceback (most recent call last):
  File "/opt/ros/kinetic/lib/python2.7/dist-packages/rospy/topics.py", line 750, in _invoke_callback
    cb(msg)
  File "/mnt/data2/students/sub1/ccc_v1_w_OIyD_190740/asn329241_1/asn329242_1/work/catkin_ws/src/project1_solution/scripts/solution.py", line 8, in callback
    rospy.loginfo(data.a, data.b)
  File "/usr/lib/python2.7/logging/__init__.py", line 1167, in info
    self._log(INFO, msg, args, **kwargs)
  File "/usr/lib/python2.7/logging/__init__.py", line 1286, in _log
    self.handle(record)
  File "/usr/lib/python2.7/logging/__init__.py", line 1296, in handle
    self.callHandlers(record)
  File "/usr/lib/python2.7/logging/__init__.py", line 1336, in callHandlers
    hdlr.handle(record)
  File "/usr/lib/python2.7/logging/__init__.py", line 759, in handle
    self.emit(record)
  File "/opt/ros/kinetic/lib/python2.7/dist-packages/rosgraph/roslogging.py", line 182, in emit
    record_message = _defaultFormatter.format(record)
  File "/usr/lib/python2.7/logging/__init__.py", line 465, in format
    record.message = record.getMessage()
  File "/usr/lib/python2.7/logging/__init__.py", line 329, in getMessage
    msg = msg % self.args
TypeError: not all arguments converted during string formatting

[rosout][ERROR] 2021-02-12 16:37:18,855: bad callback: <function callback at 0x7f5e2807c5f0>
Traceback (most recent call last):
  File "/opt/ros/kinetic/lib/python2.7/dist-packages/rospy/topics.py", line 750, in _invoke_callback
    cb(msg)
  File "/mnt/data2/students/sub1/ccc_v1_w_OIyD_190740/asn329241_1/asn329242_1/work/catkin_ws/src/project1_solution/scripts/solution.py", line 8, in callback
    rospy.loginfo(data.a, data.b)
  File "/usr/lib/python2.7/logging/__init__.py", line 1167, in info
    self._log(INFO, msg, args, **kwargs)
  File "/usr/lib/python2.7/logging/__init__.py", line 1286, in _log
    self.handle(record)
  File "/usr/lib/python2.7/logging/__init__.py", line 1296, in handle
    self.callHandlers(record)
  File "/usr/lib/python2.7/logging/__init__.py", line 1336, in callHandlers
    hdlr.handle(record)
  File "/usr/lib/python2.7/logging/__init__.py", line 759, in handle
    self.emit(record)
  File "/opt/ros/kinetic/lib/python2.7/dist-packages/rosgraph/roslogging.py", line 182, in emit
    record_message = _defaultFormatter.format(record)
  File "/usr/lib/python2.7/logging/__init__.py", line 465, in format
    record.message = record.getMessage()
  File "/usr/lib/python2.7/logging/__init__.py", line 329, in getMessage
    msg = msg % self.args
TypeError: not all arguments converted during string formatting

[rosout][ERROR] 2021-02-12 16:37:20,855: bad callback: <function callback at 0x7f5e2807c5f0>
Traceback (most recent call last):
  File "/opt/ros/kinetic/lib/python2.7/dist-packages/rospy/topics.py", line 750, in _invoke_callback
    cb(msg)
  File "/mnt/data2/students/sub1/ccc_v1_w_OIyD_190740/asn329241_1/asn329242_1/work/catkin_ws/src/project1_solution/scripts/solution.py", line 8, in callback
    rospy.loginfo(data.a, data.b)
  File "/usr/lib/python2.7/logging/__init__.py", line 1167, in info
    self._log(INFO, msg, args, **kwargs)
  File "/usr/lib/python2.7/logging/__init__.py", line 1286, in _log
    self.handle(record)
  File "/usr/lib/python2.7/logging/__init__.py", line 1296, in handle
    self.callHandlers(record)
  File "/usr/lib/python2.7/logging/__init__.py", line 1336, in callHandlers
    hdlr.handle(record)
  File "/usr/lib/python2.7/logging/__init__.py", line 759, in handle
    self.emit(record)
  File "/opt/ros/kinetic/lib/python2.7/dist-packages/rosgraph/roslogging.py", line 182, in emit
    record_message = _defaultFormatter.format(record)
  File "/usr/lib/python2.7/logging/__init__.py", line 465, in format
    record.message = record.getMessage()
  File "/usr/lib/python2.7/logging/__init__.py", line 329, in getMessage
    msg = msg % self.args
TypeError: not all arguments converted during string formatting

[rosout][ERROR] 2021-02-12 16:37:22,854: bad callback: <function callback at 0x7f5e2807c5f0>
Traceback (most recent call last):
  File "/opt/ros/kinetic/lib/python2.7/dist-packages/rospy/topics.py", line 750, in _invoke_callback
    cb(msg)
  File "/mnt/data2/students/sub1/ccc_v1_w_OIyD_190740/asn329241_1/asn329242_1/work/catkin_ws/src/project1_solution/scripts/solution.py", line 8, in callback
    rospy.loginfo(data.a, data.b)
  File "/usr/lib/python2.7/logging/__init__.py", line 1167, in info
    self._log(INFO, msg, args, **kwargs)
  File "/usr/lib/python2.7/logging/__init__.py", line 1286, in _log
    self.handle(record)
  File "/usr/lib/python2.7/logging/__init__.py", line 1296, in handle
    self.callHandlers(record)
  File "/usr/lib/python2.7/logging/__init__.py", line 1336, in callHandlers
    hdlr.handle(record)
  File "/usr/lib/python2.7/logging/__init__.py", line 759, in handle
    self.emit(record)
  File "/opt/ros/kinetic/lib/python2.7/dist-packages/rosgraph/roslogging.py", line 182, in emit
    record_message = _defaultFormatter.format(record)
  File "/usr/lib/python2.7/logging/__init__.py", line 465, in format
    record.message = record.getMessage()
  File "/usr/lib/python2.7/logging/__init__.py", line 329, in getMessage
    msg = msg % self.args
TypeError: not all arguments converted during string formatting

[rosout][ERROR] 2021-02-12 16:37:24,855: bad callback: <function callback at 0x7f5e2807c5f0>
Traceback (most recent call last):
  File "/opt/ros/kinetic/lib/python2.7/dist-packages/rospy/topics.py", line 750, in _invoke_callback
    cb(msg)
  File "/mnt/data2/students/sub1/ccc_v1_w_OIyD_190740/asn329241_1/asn329242_1/work/catkin_ws/src/project1_solution/scripts/solution.py", line 8, in callback
    rospy.loginfo(data.a, data.b)
  File "/usr/lib/python2.7/logging/__init__.py", line 1167, in info
    self._log(INFO, msg, args, **kwargs)
  File "/usr/lib/python2.7/logging/__init__.py", line 1286, in _log
    self.handle(record)
  File "/usr/lib/python2.7/logging/__init__.py", line 1296, in handle
    self.callHandlers(record)
  File "/usr/lib/python2.7/logging/__init__.py", line 1336, in callHandlers
    hdlr.handle(record)
  File "/usr/lib/python2.7/logging/__init__.py", line 759, in handle
    self.emit(record)
  File "/opt/ros/kinetic/lib/python2.7/dist-packages/rosgraph/roslogging.py", line 182, in emit
    record_message = _defaultFormatter.format(record)
  File "/usr/lib/python2.7/logging/__init__.py", line 465, in format
    record.message = record.getMessage()
  File "/usr/lib/python2.7/logging/__init__.py", line 329, in getMessage
    msg = msg % self.args
TypeError: not all arguments converted during string formatting

[rosout][ERROR] 2021-02-12 16:37:26,856: bad callback: <function callback at 0x7f5e2807c5f0>
Traceback (most recent call last):
  File "/opt/ros/kinetic/lib/python2.7/dist-packages/rospy/topics.py", line 750, in _invoke_callback
    cb(msg)
  File "/mnt/data2/students/sub1/ccc_v1_w_OIyD_190740/asn329241_1/asn329242_1/work/catkin_ws/src/project1_solution/scripts/solution.py", line 8, in callback
    rospy.loginfo(data.a, data.b)
  File "/usr/lib/python2.7/logging/__init__.py", line 1167, in info
    self._log(INFO, msg, args, **kwargs)
  File "/usr/lib/python2.7/logging/__init__.py", line 1286, in _log
    self.handle(record)
  File "/usr/lib/python2.7/logging/__init__.py", line 1296, in handle
    self.callHandlers(record)
  File "/usr/lib/python2.7/logging/__init__.py", line 1336, in callHandlers
    hdlr.handle(record)
  File "/usr/lib/python2.7/logging/__init__.py", line 759, in handle
    self.emit(record)
  File "/opt/ros/kinetic/lib/python2.7/dist-packages/rosgraph/roslogging.py", line 182, in emit
    record_message = _defaultFormatter.format(record)
  File "/usr/lib/python2.7/logging/__init__.py", line 465, in format
    record.message = record.getMessage()
  File "/usr/lib/python2.7/logging/__init__.py", line 329, in getMessage
    msg = msg % self.args
TypeError: not all arguments converted during string formatting

[rosout][ERROR] 2021-02-12 16:37:28,856: bad callback: <function callback at 0x7f5e2807c5f0>
Traceback (most recent call last):
  File "/opt/ros/kinetic/lib/python2.7/dist-packages/rospy/topics.py", line 750, in _invoke_callback
    cb(msg)
  File "/mnt/data2/students/sub1/ccc_v1_w_OIyD_190740/asn329241_1/asn329242_1/work/catkin_ws/src/project1_solution/scripts/solution.py", line 8, in callback
    rospy.loginfo(data.a, data.b)
  File "/usr/lib/python2.7/logging/__init__.py", line 1167, in info
    self._log(INFO, msg, args, **kwargs)
  File "/usr/lib/python2.7/logging/__init__.py", line 1286, in _log
    self.handle(record)
  File "/usr/lib/python2.7/logging/__init__.py", line 1296, in handle
    self.callHandlers(record)
  File "/usr/lib/python2.7/logging/__init__.py", line 1336, in callHandlers
    hdlr.handle(record)
  File "/usr/lib/python2.7/logging/__init__.py", line 759, in handle
    self.emit(record)
  File "/opt/ros/kinetic/lib/python2.7/dist-packages/rosgraph/roslogging.py", line 182, in emit
    record_message = _defaultFormatter.format(record)
  File "/usr/lib/python2.7/logging/__init__.py", line 465, in format
    record.message = record.getMessage()
  File "/usr/lib/python2.7/logging/__init__.py", line 329, in getMessage
    msg = msg % self.args
TypeError: not all arguments converted during string formatting

[rosout][ERROR] 2021-02-12 16:37:30,855: bad callback: <function callback at 0x7f5e2807c5f0>
Traceback (most recent call last):
  File "/opt/ros/kinetic/lib/python2.7/dist-packages/rospy/topics.py", line 750, in _invoke_callback
    cb(msg)
  File "/mnt/data2/students/sub1/ccc_v1_w_OIyD_190740/asn329241_1/asn329242_1/work/catkin_ws/src/project1_solution/scripts/solution.py", line 8, in callback
    rospy.loginfo(data.a, data.b)
  File "/usr/lib/python2.7/logging/__init__.py", line 1167, in info
    self._log(INFO, msg, args, **kwargs)
  File "/usr/lib/python2.7/logging/__init__.py", line 1286, in _log
    self.handle(record)
  File "/usr/lib/python2.7/logging/__init__.py", line 1296, in handle
    self.callHandlers(record)
  File "/usr/lib/python2.7/logging/__init__.py", line 1336, in callHandlers
    hdlr.handle(record)
  File "/usr/lib/python2.7/logging/__init__.py", line 759, in handle
    self.emit(record)
  File "/opt/ros/kinetic/lib/python2.7/dist-packages/rosgraph/roslogging.py", line 182, in emit
    record_message = _defaultFormatter.format(record)
  File "/usr/lib/python2.7/logging/__init__.py", line 465, in format
    record.message = record.getMessage()
  File "/usr/lib/python2.7/logging/__init__.py", line 329, in getMessage
    msg = msg % self.args
TypeError: not all arguments converted during string formatting

[rosout][ERROR] 2021-02-12 16:37:32,854: bad callback: <function callback at 0x7f5e2807c5f0>
Traceback (most recent call last):
  File "/opt/ros/kinetic/lib/python2.7/dist-packages/rospy/topics.py", line 750, in _invoke_callback
    cb(msg)
  File "/mnt/data2/students/sub1/ccc_v1_w_OIyD_190740/asn329241_1/asn329242_1/work/catkin_ws/src/project1_solution/scripts/solution.py", line 8, in callback
    rospy.loginfo(data.a, data.b)
  File "/usr/lib/python2.7/logging/__init__.py", line 1167, in info
    self._log(INFO, msg, args, **kwargs)
  File "/usr/lib/python2.7/logging/__init__.py", line 1286, in _log
    self.handle(record)
  File "/usr/lib/python2.7/logging/__init__.py", line 1296, in handle
    self.callHandlers(record)
  File "/usr/lib/python2.7/logging/__init__.py", line 1336, in callHandlers
    hdlr.handle(record)
  File "/usr/lib/python2.7/logging/__init__.py", line 759, in handle
    self.emit(record)
  File "/opt/ros/kinetic/lib/python2.7/dist-packages/rosgraph/roslogging.py", line 182, in emit
    record_message = _defaultFormatter.format(record)
  File "/usr/lib/python2.7/logging/__init__.py", line 465, in format
    record.message = record.getMessage()
  File "/usr/lib/python2.7/logging/__init__.py", line 329, in getMessage
    msg = msg % self.args
TypeError: not all arguments converted during string formatting

[rosout][ERROR] 2021-02-12 16:37:34,855: bad callback: <function callback at 0x7f5e2807c5f0>
Traceback (most recent call last):
  File "/opt/ros/kinetic/lib/python2.7/dist-packages/rospy/topics.py", line 750, in _invoke_callback
    cb(msg)
  File "/mnt/data2/students/sub1/ccc_v1_w_OIyD_190740/asn329241_1/asn329242_1/work/catkin_ws/src/project1_solution/scripts/solution.py", line 8, in callback
    rospy.loginfo(data.a, data.b)
  File "/usr/lib/python2.7/logging/__init__.py", line 1167, in info
    self._log(INFO, msg, args, **kwargs)
  File "/usr/lib/python2.7/logging/__init__.py", line 1286, in _log
    self.handle(record)
  File "/usr/lib/python2.7/logging/__init__.py", line 1296, in handle
    self.callHandlers(record)
  File "/usr/lib/python2.7/logging/__init__.py", line 1336, in callHandlers
    hdlr.handle(record)
  File "/usr/lib/python2.7/logging/__init__.py", line 759, in handle
    self.emit(record)
  File "/opt/ros/kinetic/lib/python2.7/dist-packages/rosgraph/roslogging.py", line 182, in emit
    record_message = _defaultFormatter.format(record)
  File "/usr/lib/python2.7/logging/__init__.py", line 465, in format
    record.message = record.getMessage()
  File "/usr/lib/python2.7/logging/__init__.py", line 329, in getMessage
    msg = msg % self.args
TypeError: not all arguments converted during string formatting

[rosout][ERROR] 2021-02-12 16:37:36,854: bad callback: <function callback at 0x7f5e2807c5f0>
Traceback (most recent call last):
  File "/opt/ros/kinetic/lib/python2.7/dist-packages/rospy/topics.py", line 750, in _invoke_callback
    cb(msg)
  File "/mnt/data2/students/sub1/ccc_v1_w_OIyD_190740/asn329241_1/asn329242_1/work/catkin_ws/src/project1_solution/scripts/solution.py", line 8, in callback
    rospy.loginfo(data.a, data.b)
  File "/usr/lib/python2.7/logging/__init__.py", line 1167, in info
    self._log(INFO, msg, args, **kwargs)
  File "/usr/lib/python2.7/logging/__init__.py", line 1286, in _log
    self.handle(record)
  File "/usr/lib/python2.7/logging/__init__.py", line 1296, in handle
    self.callHandlers(record)
  File "/usr/lib/python2.7/logging/__init__.py", line 1336, in callHandlers
    hdlr.handle(record)
  File "/usr/lib/python2.7/logging/__init__.py", line 759, in handle
    self.emit(record)
  File "/opt/ros/kinetic/lib/python2.7/dist-packages/rosgraph/roslogging.py", line 182, in emit
    record_message = _defaultFormatter.format(record)
  File "/usr/lib/python2.7/logging/__init__.py", line 465, in format
    record.message = record.getMessage()
  File "/usr/lib/python2.7/logging/__init__.py", line 329, in getMessage
    msg = msg % self.args
TypeError: not all arguments converted during string formatting

[rosout][ERROR] 2021-02-12 16:37:38,857: bad callback: <function callback at 0x7f5e2807c5f0>
Traceback (most recent call last):
  File "/opt/ros/kinetic/lib/python2.7/dist-packages/rospy/topics.py", line 750, in _invoke_callback
    cb(msg)
  File "/mnt/data2/students/sub1/ccc_v1_w_OIyD_190740/asn329241_1/asn329242_1/work/catkin_ws/src/project1_solution/scripts/solution.py", line 8, in callback
    rospy.loginfo(data.a, data.b)
  File "/usr/lib/python2.7/logging/__init__.py", line 1167, in info
    self._log(INFO, msg, args, **kwargs)
  File "/usr/lib/python2.7/logging/__init__.py", line 1286, in _log
    self.handle(record)
  File "/usr/lib/python2.7/logging/__init__.py", line 1296, in handle
    self.callHandlers(record)
  File "/usr/lib/python2.7/logging/__init__.py", line 1336, in callHandlers
    hdlr.handle(record)
  File "/usr/lib/python2.7/logging/__init__.py", line 759, in handle
    self.emit(record)
  File "/opt/ros/kinetic/lib/python2.7/dist-packages/rosgraph/roslogging.py", line 182, in emit
    record_message = _defaultFormatter.format(record)
  File "/usr/lib/python2.7/logging/__init__.py", line 465, in format
    record.message = record.getMessage()
  File "/usr/lib/python2.7/logging/__init__.py", line 329, in getMessage
    msg = msg % self.args
TypeError: not all arguments converted during string formatting

[rosout][ERROR] 2021-02-12 16:37:40,854: bad callback: <function callback at 0x7f5e2807c5f0>
Traceback (most recent call last):
  File "/opt/ros/kinetic/lib/python2.7/dist-packages/rospy/topics.py", line 750, in _invoke_callback
    cb(msg)
  File "/mnt/data2/students/sub1/ccc_v1_w_OIyD_190740/asn329241_1/asn329242_1/work/catkin_ws/src/project1_solution/scripts/solution.py", line 8, in callback
    rospy.loginfo(data.a, data.b)
  File "/usr/lib/python2.7/logging/__init__.py", line 1167, in info
    self._log(INFO, msg, args, **kwargs)
  File "/usr/lib/python2.7/logging/__init__.py", line 1286, in _log
    self.handle(record)
  File "/usr/lib/python2.7/logging/__init__.py", line 1296, in handle
    self.callHandlers(record)
  File "/usr/lib/python2.7/logging/__init__.py", line 1336, in callHandlers
    hdlr.handle(record)
  File "/usr/lib/python2.7/logging/__init__.py", line 759, in handle
    self.emit(record)
  File "/opt/ros/kinetic/lib/python2.7/dist-packages/rosgraph/roslogging.py", line 182, in emit
    record_message = _defaultFormatter.format(record)
  File "/usr/lib/python2.7/logging/__init__.py", line 465, in format
    record.message = record.getMessage()
  File "/usr/lib/python2.7/logging/__init__.py", line 329, in getMessage
    msg = msg % self.args
TypeError: not all arguments converted during string formatting

[rosout][ERROR] 2021-02-12 16:37:42,855: bad callback: <function callback at 0x7f5e2807c5f0>
Traceback (most recent call last):
  File "/opt/ros/kinetic/lib/python2.7/dist-packages/rospy/topics.py", line 750, in _invoke_callback
    cb(msg)
  File "/mnt/data2/students/sub1/ccc_v1_w_OIyD_190740/asn329241_1/asn329242_1/work/catkin_ws/src/project1_solution/scripts/solution.py", line 8, in callback
    rospy.loginfo(data.a, data.b)
  File "/usr/lib/python2.7/logging/__init__.py", line 1167, in info
    self._log(INFO, msg, args, **kwargs)
  File "/usr/lib/python2.7/logging/__init__.py", line 1286, in _log
    self.handle(record)
  File "/usr/lib/python2.7/logging/__init__.py", line 1296, in handle
    self.callHandlers(record)
  File "/usr/lib/python2.7/logging/__init__.py", line 1336, in callHandlers
    hdlr.handle(record)
  File "/usr/lib/python2.7/logging/__init__.py", line 759, in handle
    self.emit(record)
  File "/opt/ros/kinetic/lib/python2.7/dist-packages/rosgraph/roslogging.py", line 182, in emit
    record_message = _defaultFormatter.format(record)
  File "/usr/lib/python2.7/logging/__init__.py", line 465, in format
    record.message = record.getMessage()
  File "/usr/lib/python2.7/logging/__init__.py", line 329, in getMessage
    msg = msg % self.args
TypeError: not all arguments converted during string formatting

[rosout][ERROR] 2021-02-12 16:37:44,855: bad callback: <function callback at 0x7f5e2807c5f0>
Traceback (most recent call last):
  File "/opt/ros/kinetic/lib/python2.7/dist-packages/rospy/topics.py", line 750, in _invoke_callback
    cb(msg)
  File "/mnt/data2/students/sub1/ccc_v1_w_OIyD_190740/asn329241_1/asn329242_1/work/catkin_ws/src/project1_solution/scripts/solution.py", line 8, in callback
    rospy.loginfo(data.a, data.b)
  File "/usr/lib/python2.7/logging/__init__.py", line 1167, in info
    self._log(INFO, msg, args, **kwargs)
  File "/usr/lib/python2.7/logging/__init__.py", line 1286, in _log
    self.handle(record)
  File "/usr/lib/python2.7/logging/__init__.py", line 1296, in handle
    self.callHandlers(record)
  File "/usr/lib/python2.7/logging/__init__.py", line 1336, in callHandlers
    hdlr.handle(record)
  File "/usr/lib/python2.7/logging/__init__.py", line 759, in handle
    self.emit(record)
  File "/opt/ros/kinetic/lib/python2.7/dist-packages/rosgraph/roslogging.py", line 182, in emit
    record_message = _defaultFormatter.format(record)
  File "/usr/lib/python2.7/logging/__init__.py", line 465, in format
    record.message = record.getMessage()
  File "/usr/lib/python2.7/logging/__init__.py", line 329, in getMessage
    msg = msg % self.args
TypeError: not all arguments converted during string formatting

[rosout][ERROR] 2021-02-12 16:37:46,854: bad callback: <function callback at 0x7f5e2807c5f0>
Traceback (most recent call last):
  File "/opt/ros/kinetic/lib/python2.7/dist-packages/rospy/topics.py", line 750, in _invoke_callback
    cb(msg)
  File "/mnt/data2/students/sub1/ccc_v1_w_OIyD_190740/asn329241_1/asn329242_1/work/catkin_ws/src/project1_solution/scripts/solution.py", line 8, in callback
    rospy.loginfo(data.a, data.b)
  File "/usr/lib/python2.7/logging/__init__.py", line 1167, in info
    self._log(INFO, msg, args, **kwargs)
  File "/usr/lib/python2.7/logging/__init__.py", line 1286, in _log
    self.handle(record)
  File "/usr/lib/python2.7/logging/__init__.py", line 1296, in handle
    self.callHandlers(record)
  File "/usr/lib/python2.7/logging/__init__.py", line 1336, in callHandlers
    hdlr.handle(record)
  File "/usr/lib/python2.7/logging/__init__.py", line 759, in handle
    self.emit(record)
  File "/opt/ros/kinetic/lib/python2.7/dist-packages/rosgraph/roslogging.py", line 182, in emit
    record_message = _defaultFormatter.format(record)
  File "/usr/lib/python2.7/logging/__init__.py", line 465, in format
    record.message = record.getMessage()
  File "/usr/lib/python2.7/logging/__init__.py", line 329, in getMessage
    msg = msg % self.args
TypeError: not all arguments converted during string formatting

[rosout][ERROR] 2021-02-12 16:37:48,854: bad callback: <function callback at 0x7f5e2807c5f0>
Traceback (most recent call last):
  File "/opt/ros/kinetic/lib/python2.7/dist-packages/rospy/topics.py", line 750, in _invoke_callback
    cb(msg)
  File "/mnt/data2/students/sub1/ccc_v1_w_OIyD_190740/asn329241_1/asn329242_1/work/catkin_ws/src/project1_solution/scripts/solution.py", line 8, in callback
    rospy.loginfo(data.a, data.b)
  File "/usr/lib/python2.7/logging/__init__.py", line 1167, in info
    self._log(INFO, msg, args, **kwargs)
  File "/usr/lib/python2.7/logging/__init__.py", line 1286, in _log
    self.handle(record)
  File "/usr/lib/python2.7/logging/__init__.py", line 1296, in handle
    self.callHandlers(record)
  File "/usr/lib/python2.7/logging/__init__.py", line 1336, in callHandlers
    hdlr.handle(record)
  File "/usr/lib/python2.7/logging/__init__.py", line 759, in handle
    self.emit(record)
  File "/opt/ros/kinetic/lib/python2.7/dist-packages/rosgraph/roslogging.py", line 182, in emit
    record_message = _defaultFormatter.format(record)
  File "/usr/lib/python2.7/logging/__init__.py", line 465, in format
    record.message = record.getMessage()
  File "/usr/lib/python2.7/logging/__init__.py", line 329, in getMessage
    msg = msg % self.args
TypeError: not all arguments converted during string formatting

[rosout][ERROR] 2021-02-12 16:37:50,854: bad callback: <function callback at 0x7f5e2807c5f0>
Traceback (most recent call last):
  File "/opt/ros/kinetic/lib/python2.7/dist-packages/rospy/topics.py", line 750, in _invoke_callback
    cb(msg)
  File "/mnt/data2/students/sub1/ccc_v1_w_OIyD_190740/asn329241_1/asn329242_1/work/catkin_ws/src/project1_solution/scripts/solution.py", line 8, in callback
    rospy.loginfo(data.a, data.b)
  File "/usr/lib/python2.7/logging/__init__.py", line 1167, in info
    self._log(INFO, msg, args, **kwargs)
  File "/usr/lib/python2.7/logging/__init__.py", line 1286, in _log
    self.handle(record)
  File "/usr/lib/python2.7/logging/__init__.py", line 1296, in handle
    self.callHandlers(record)
  File "/usr/lib/python2.7/logging/__init__.py", line 1336, in callHandlers
    hdlr.handle(record)
  File "/usr/lib/python2.7/logging/__init__.py", line 759, in handle
    self.emit(record)
  File "/opt/ros/kinetic/lib/python2.7/dist-packages/rosgraph/roslogging.py", line 182, in emit
    record_message = _defaultFormatter.format(record)
  File "/usr/lib/python2.7/logging/__init__.py", line 465, in format
    record.message = record.getMessage()
  File "/usr/lib/python2.7/logging/__init__.py", line 329, in getMessage
    msg = msg % self.args
TypeError: not all arguments converted during string formatting

[rosout][ERROR] 2021-02-12 16:37:52,856: bad callback: <function callback at 0x7f5e2807c5f0>
Traceback (most recent call last):
  File "/opt/ros/kinetic/lib/python2.7/dist-packages/rospy/topics.py", line 750, in _invoke_callback
    cb(msg)
  File "/mnt/data2/students/sub1/ccc_v1_w_OIyD_190740/asn329241_1/asn329242_1/work/catkin_ws/src/project1_solution/scripts/solution.py", line 8, in callback
    rospy.loginfo(data.a, data.b)
  File "/usr/lib/python2.7/logging/__init__.py", line 1167, in info
    self._log(INFO, msg, args, **kwargs)
  File "/usr/lib/python2.7/logging/__init__.py", line 1286, in _log
    self.handle(record)
  File "/usr/lib/python2.7/logging/__init__.py", line 1296, in handle
    self.callHandlers(record)
  File "/usr/lib/python2.7/logging/__init__.py", line 1336, in callHandlers
    hdlr.handle(record)
  File "/usr/lib/python2.7/logging/__init__.py", line 759, in handle
    self.emit(record)
  File "/opt/ros/kinetic/lib/python2.7/dist-packages/rosgraph/roslogging.py", line 182, in emit
    record_message = _defaultFormatter.format(record)
  File "/usr/lib/python2.7/logging/__init__.py", line 465, in format
    record.message = record.getMessage()
  File "/usr/lib/python2.7/logging/__init__.py", line 329, in getMessage
    msg = msg % self.args
TypeError: not all arguments converted during string formatting

[rosout][ERROR] 2021-02-12 16:37:54,854: bad callback: <function callback at 0x7f5e2807c5f0>
Traceback (most recent call last):
  File "/opt/ros/kinetic/lib/python2.7/dist-packages/rospy/topics.py", line 750, in _invoke_callback
    cb(msg)
  File "/mnt/data2/students/sub1/ccc_v1_w_OIyD_190740/asn329241_1/asn329242_1/work/catkin_ws/src/project1_solution/scripts/solution.py", line 8, in callback
    rospy.loginfo(data.a, data.b)
  File "/usr/lib/python2.7/logging/__init__.py", line 1167, in info
    self._log(INFO, msg, args, **kwargs)
  File "/usr/lib/python2.7/logging/__init__.py", line 1286, in _log
    self.handle(record)
  File "/usr/lib/python2.7/logging/__init__.py", line 1296, in handle
    self.callHandlers(record)
  File "/usr/lib/python2.7/logging/__init__.py", line 1336, in callHandlers
    hdlr.handle(record)
  File "/usr/lib/python2.7/logging/__init__.py", line 759, in handle
    self.emit(record)
  File "/opt/ros/kinetic/lib/python2.7/dist-packages/rosgraph/roslogging.py", line 182, in emit
    record_message = _defaultFormatter.format(record)
  File "/usr/lib/python2.7/logging/__init__.py", line 465, in format
    record.message = record.getMessage()
  File "/usr/lib/python2.7/logging/__init__.py", line 329, in getMessage
    msg = msg % self.args
TypeError: not all arguments converted during string formatting

[rosout][ERROR] 2021-02-12 16:37:56,856: bad callback: <function callback at 0x7f5e2807c5f0>
Traceback (most recent call last):
  File "/opt/ros/kinetic/lib/python2.7/dist-packages/rospy/topics.py", line 750, in _invoke_callback
    cb(msg)
  File "/mnt/data2/students/sub1/ccc_v1_w_OIyD_190740/asn329241_1/asn329242_1/work/catkin_ws/src/project1_solution/scripts/solution.py", line 8, in callback
    rospy.loginfo(data.a, data.b)
  File "/usr/lib/python2.7/logging/__init__.py", line 1167, in info
    self._log(INFO, msg, args, **kwargs)
  File "/usr/lib/python2.7/logging/__init__.py", line 1286, in _log
    self.handle(record)
  File "/usr/lib/python2.7/logging/__init__.py", line 1296, in handle
    self.callHandlers(record)
  File "/usr/lib/python2.7/logging/__init__.py", line 1336, in callHandlers
    hdlr.handle(record)
  File "/usr/lib/python2.7/logging/__init__.py", line 759, in handle
    self.emit(record)
  File "/opt/ros/kinetic/lib/python2.7/dist-packages/rosgraph/roslogging.py", line 182, in emit
    record_message = _defaultFormatter.format(record)
  File "/usr/lib/python2.7/logging/__init__.py", line 465, in format
    record.message = record.getMessage()
  File "/usr/lib/python2.7/logging/__init__.py", line 329, in getMessage
    msg = msg % self.args
TypeError: not all arguments converted during string formatting

[rosout][ERROR] 2021-02-12 16:37:58,854: bad callback: <function callback at 0x7f5e2807c5f0>
Traceback (most recent call last):
  File "/opt/ros/kinetic/lib/python2.7/dist-packages/rospy/topics.py", line 750, in _invoke_callback
    cb(msg)
  File "/mnt/data2/students/sub1/ccc_v1_w_OIyD_190740/asn329241_1/asn329242_1/work/catkin_ws/src/project1_solution/scripts/solution.py", line 8, in callback
    rospy.loginfo(data.a, data.b)
  File "/usr/lib/python2.7/logging/__init__.py", line 1167, in info
    self._log(INFO, msg, args, **kwargs)
  File "/usr/lib/python2.7/logging/__init__.py", line 1286, in _log
    self.handle(record)
  File "/usr/lib/python2.7/logging/__init__.py", line 1296, in handle
    self.callHandlers(record)
  File "/usr/lib/python2.7/logging/__init__.py", line 1336, in callHandlers
    hdlr.handle(record)
  File "/usr/lib/python2.7/logging/__init__.py", line 759, in handle
    self.emit(record)
  File "/opt/ros/kinetic/lib/python2.7/dist-packages/rosgraph/roslogging.py", line 182, in emit
    record_message = _defaultFormatter.format(record)
  File "/usr/lib/python2.7/logging/__init__.py", line 465, in format
    record.message = record.getMessage()
  File "/usr/lib/python2.7/logging/__init__.py", line 329, in getMessage
    msg = msg % self.args
TypeError: not all arguments converted during string formatting

[rosout][ERROR] 2021-02-12 16:38:00,854: bad callback: <function callback at 0x7f5e2807c5f0>
Traceback (most recent call last):
  File "/opt/ros/kinetic/lib/python2.7/dist-packages/rospy/topics.py", line 750, in _invoke_callback
    cb(msg)
  File "/mnt/data2/students/sub1/ccc_v1_w_OIyD_190740/asn329241_1/asn329242_1/work/catkin_ws/src/project1_solution/scripts/solution.py", line 8, in callback
    rospy.loginfo(data.a, data.b)
  File "/usr/lib/python2.7/logging/__init__.py", line 1167, in info
    self._log(INFO, msg, args, **kwargs)
  File "/usr/lib/python2.7/logging/__init__.py", line 1286, in _log
    self.handle(record)
  File "/usr/lib/python2.7/logging/__init__.py", line 1296, in handle
    self.callHandlers(record)
  File "/usr/lib/python2.7/logging/__init__.py", line 1336, in callHandlers
    hdlr.handle(record)
  File "/usr/lib/python2.7/logging/__init__.py", line 759, in handle
    self.emit(record)
  File "/opt/ros/kinetic/lib/python2.7/dist-packages/rosgraph/roslogging.py", line 182, in emit
    record_message = _defaultFormatter.format(record)
  File "/usr/lib/python2.7/logging/__init__.py", line 465, in format
    record.message = record.getMessage()
  File "/usr/lib/python2.7/logging/__init__.py", line 329, in getMessage
    msg = msg % self.args
TypeError: not all arguments converted during string formatting

[rosout][ERROR] 2021-02-12 16:38:02,855: bad callback: <function callback at 0x7f5e2807c5f0>
Traceback (most recent call last):
  File "/opt/ros/kinetic/lib/python2.7/dist-packages/rospy/topics.py", line 750, in _invoke_callback
    cb(msg)
  File "/mnt/data2/students/sub1/ccc_v1_w_OIyD_190740/asn329241_1/asn329242_1/work/catkin_ws/src/project1_solution/scripts/solution.py", line 8, in callback
    rospy.loginfo(data.a, data.b)
  File "/usr/lib/python2.7/logging/__init__.py", line 1167, in info
    self._log(INFO, msg, args, **kwargs)
  File "/usr/lib/python2.7/logging/__init__.py", line 1286, in _log
    self.handle(record)
  File "/usr/lib/python2.7/logging/__init__.py", line 1296, in handle
    self.callHandlers(record)
  File "/usr/lib/python2.7/logging/__init__.py", line 1336, in callHandlers
    hdlr.handle(record)
  File "/usr/lib/python2.7/logging/__init__.py", line 759, in handle
    self.emit(record)
  File "/opt/ros/kinetic/lib/python2.7/dist-packages/rosgraph/roslogging.py", line 182, in emit
    record_message = _defaultFormatter.format(record)
  File "/usr/lib/python2.7/logging/__init__.py", line 465, in format
    record.message = record.getMessage()
  File "/usr/lib/python2.7/logging/__init__.py", line 329, in getMessage
    msg = msg % self.args
TypeError: not all arguments converted during string formatting

[rosout][ERROR] 2021-02-12 16:38:04,854: bad callback: <function callback at 0x7f5e2807c5f0>
Traceback (most recent call last):
  File "/opt/ros/kinetic/lib/python2.7/dist-packages/rospy/topics.py", line 750, in _invoke_callback
    cb(msg)
  File "/mnt/data2/students/sub1/ccc_v1_w_OIyD_190740/asn329241_1/asn329242_1/work/catkin_ws/src/project1_solution/scripts/solution.py", line 8, in callback
    rospy.loginfo(data.a, data.b)
  File "/usr/lib/python2.7/logging/__init__.py", line 1167, in info
    self._log(INFO, msg, args, **kwargs)
  File "/usr/lib/python2.7/logging/__init__.py", line 1286, in _log
    self.handle(record)
  File "/usr/lib/python2.7/logging/__init__.py", line 1296, in handle
    self.callHandlers(record)
  File "/usr/lib/python2.7/logging/__init__.py", line 1336, in callHandlers
    hdlr.handle(record)
  File "/usr/lib/python2.7/logging/__init__.py", line 759, in handle
    self.emit(record)
  File "/opt/ros/kinetic/lib/python2.7/dist-packages/rosgraph/roslogging.py", line 182, in emit
    record_message = _defaultFormatter.format(record)
  File "/usr/lib/python2.7/logging/__init__.py", line 465, in format
    record.message = record.getMessage()
  File "/usr/lib/python2.7/logging/__init__.py", line 329, in getMessage
    msg = msg % self.args
TypeError: not all arguments converted during string formatting

[rosout][ERROR] 2021-02-12 16:38:06,862: bad callback: <function callback at 0x7f5e2807c5f0>
Traceback (most recent call last):
  File "/opt/ros/kinetic/lib/python2.7/dist-packages/rospy/topics.py", line 750, in _invoke_callback
    cb(msg)
  File "/mnt/data2/students/sub1/ccc_v1_w_OIyD_190740/asn329241_1/asn329242_1/work/catkin_ws/src/project1_solution/scripts/solution.py", line 8, in callback
    rospy.loginfo(data.a, data.b)
  File "/usr/lib/python2.7/logging/__init__.py", line 1167, in info
    self._log(INFO, msg, args, **kwargs)
  File "/usr/lib/python2.7/logging/__init__.py", line 1286, in _log
    self.handle(record)
  File "/usr/lib/python2.7/logging/__init__.py", line 1296, in handle
    self.callHandlers(record)
  File "/usr/lib/python2.7/logging/__init__.py", line 1336, in callHandlers
    hdlr.handle(record)
  File "/usr/lib/python2.7/logging/__init__.py", line 759, in handle
    self.emit(record)
  File "/opt/ros/kinetic/lib/python2.7/dist-packages/rosgraph/roslogging.py", line 182, in emit
    record_message = _defaultFormatter.format(record)
  File "/usr/lib/python2.7/logging/__init__.py", line 465, in format
    record.message = record.getMessage()
  File "/usr/lib/python2.7/logging/__init__.py", line 329, in getMessage
    msg = msg % self.args
TypeError: not all arguments converted during string formatting

[rosout][ERROR] 2021-02-12 16:38:08,855: bad callback: <function callback at 0x7f5e2807c5f0>
Traceback (most recent call last):
  File "/opt/ros/kinetic/lib/python2.7/dist-packages/rospy/topics.py", line 750, in _invoke_callback
    cb(msg)
  File "/mnt/data2/students/sub1/ccc_v1_w_OIyD_190740/asn329241_1/asn329242_1/work/catkin_ws/src/project1_solution/scripts/solution.py", line 8, in callback
    rospy.loginfo(data.a, data.b)
  File "/usr/lib/python2.7/logging/__init__.py", line 1167, in info
    self._log(INFO, msg, args, **kwargs)
  File "/usr/lib/python2.7/logging/__init__.py", line 1286, in _log
    self.handle(record)
  File "/usr/lib/python2.7/logging/__init__.py", line 1296, in handle
    self.callHandlers(record)
  File "/usr/lib/python2.7/logging/__init__.py", line 1336, in callHandlers
    hdlr.handle(record)
  File "/usr/lib/python2.7/logging/__init__.py", line 759, in handle
    self.emit(record)
  File "/opt/ros/kinetic/lib/python2.7/dist-packages/rosgraph/roslogging.py", line 182, in emit
    record_message = _defaultFormatter.format(record)
  File "/usr/lib/python2.7/logging/__init__.py", line 465, in format
    record.message = record.getMessage()
  File "/usr/lib/python2.7/logging/__init__.py", line 329, in getMessage
    msg = msg % self.args
TypeError: not all arguments converted during string formatting

[rosout][ERROR] 2021-02-12 16:38:10,855: bad callback: <function callback at 0x7f5e2807c5f0>
Traceback (most recent call last):
  File "/opt/ros/kinetic/lib/python2.7/dist-packages/rospy/topics.py", line 750, in _invoke_callback
    cb(msg)
  File "/mnt/data2/students/sub1/ccc_v1_w_OIyD_190740/asn329241_1/asn329242_1/work/catkin_ws/src/project1_solution/scripts/solution.py", line 8, in callback
    rospy.loginfo(data.a, data.b)
  File "/usr/lib/python2.7/logging/__init__.py", line 1167, in info
    self._log(INFO, msg, args, **kwargs)
  File "/usr/lib/python2.7/logging/__init__.py", line 1286, in _log
    self.handle(record)
  File "/usr/lib/python2.7/logging/__init__.py", line 1296, in handle
    self.callHandlers(record)
  File "/usr/lib/python2.7/logging/__init__.py", line 1336, in callHandlers
    hdlr.handle(record)
  File "/usr/lib/python2.7/logging/__init__.py", line 759, in handle
    self.emit(record)
  File "/opt/ros/kinetic/lib/python2.7/dist-packages/rosgraph/roslogging.py", line 182, in emit
    record_message = _defaultFormatter.format(record)
  File "/usr/lib/python2.7/logging/__init__.py", line 465, in format
    record.message = record.getMessage()
  File "/usr/lib/python2.7/logging/__init__.py", line 329, in getMessage
    msg = msg % self.args
TypeError: not all arguments converted during string formatting

[rosout][ERROR] 2021-02-12 16:38:12,855: bad callback: <function callback at 0x7f5e2807c5f0>
Traceback (most recent call last):
  File "/opt/ros/kinetic/lib/python2.7/dist-packages/rospy/topics.py", line 750, in _invoke_callback
    cb(msg)
  File "/mnt/data2/students/sub1/ccc_v1_w_OIyD_190740/asn329241_1/asn329242_1/work/catkin_ws/src/project1_solution/scripts/solution.py", line 8, in callback
    rospy.loginfo(data.a, data.b)
  File "/usr/lib/python2.7/logging/__init__.py", line 1167, in info
    self._log(INFO, msg, args, **kwargs)
  File "/usr/lib/python2.7/logging/__init__.py", line 1286, in _log
    self.handle(record)
  File "/usr/lib/python2.7/logging/__init__.py", line 1296, in handle
    self.callHandlers(record)
  File "/usr/lib/python2.7/logging/__init__.py", line 1336, in callHandlers
    hdlr.handle(record)
  File "/usr/lib/python2.7/logging/__init__.py", line 759, in handle
    self.emit(record)
  File "/opt/ros/kinetic/lib/python2.7/dist-packages/rosgraph/roslogging.py", line 182, in emit
    record_message = _defaultFormatter.format(record)
  File "/usr/lib/python2.7/logging/__init__.py", line 465, in format
    record.message = record.getMessage()
  File "/usr/lib/python2.7/logging/__init__.py", line 329, in getMessage
    msg = msg % self.args
TypeError: not all arguments converted during string formatting

[rosout][ERROR] 2021-02-12 16:38:14,856: bad callback: <function callback at 0x7f5e2807c5f0>
Traceback (most recent call last):
  File "/opt/ros/kinetic/lib/python2.7/dist-packages/rospy/topics.py", line 750, in _invoke_callback
    cb(msg)
  File "/mnt/data2/students/sub1/ccc_v1_w_OIyD_190740/asn329241_1/asn329242_1/work/catkin_ws/src/project1_solution/scripts/solution.py", line 8, in callback
    rospy.loginfo(data.a, data.b)
  File "/usr/lib/python2.7/logging/__init__.py", line 1167, in info
    self._log(INFO, msg, args, **kwargs)
  File "/usr/lib/python2.7/logging/__init__.py", line 1286, in _log
    self.handle(record)
  File "/usr/lib/python2.7/logging/__init__.py", line 1296, in handle
    self.callHandlers(record)
  File "/usr/lib/python2.7/logging/__init__.py", line 1336, in callHandlers
    hdlr.handle(record)
  File "/usr/lib/python2.7/logging/__init__.py", line 759, in handle
    self.emit(record)
  File "/opt/ros/kinetic/lib/python2.7/dist-packages/rosgraph/roslogging.py", line 182, in emit
    record_message = _defaultFormatter.format(record)
  File "/usr/lib/python2.7/logging/__init__.py", line 465, in format
    record.message = record.getMessage()
  File "/usr/lib/python2.7/logging/__init__.py", line 329, in getMessage
    msg = msg % self.args
TypeError: not all arguments converted during string formatting

[rosout][ERROR] 2021-02-12 16:38:16,855: bad callback: <function callback at 0x7f5e2807c5f0>
Traceback (most recent call last):
  File "/opt/ros/kinetic/lib/python2.7/dist-packages/rospy/topics.py", line 750, in _invoke_callback
    cb(msg)
  File "/mnt/data2/students/sub1/ccc_v1_w_OIyD_190740/asn329241_1/asn329242_1/work/catkin_ws/src/project1_solution/scripts/solution.py", line 8, in callback
    rospy.loginfo(data.a, data.b)
  File "/usr/lib/python2.7/logging/__init__.py", line 1167, in info
    self._log(INFO, msg, args, **kwargs)
  File "/usr/lib/python2.7/logging/__init__.py", line 1286, in _log
    self.handle(record)
  File "/usr/lib/python2.7/logging/__init__.py", line 1296, in handle
    self.callHandlers(record)
  File "/usr/lib/python2.7/logging/__init__.py", line 1336, in callHandlers
    hdlr.handle(record)
  File "/usr/lib/python2.7/logging/__init__.py", line 759, in handle
    self.emit(record)
  File "/opt/ros/kinetic/lib/python2.7/dist-packages/rosgraph/roslogging.py", line 182, in emit
    record_message = _defaultFormatter.format(record)
  File "/usr/lib/python2.7/logging/__init__.py", line 465, in format
    record.message = record.getMessage()
  File "/usr/lib/python2.7/logging/__init__.py", line 329, in getMessage
    msg = msg % self.args
TypeError: not all arguments converted during string formatting

[rosout][ERROR] 2021-02-12 16:38:18,854: bad callback: <function callback at 0x7f5e2807c5f0>
Traceback (most recent call last):
  File "/opt/ros/kinetic/lib/python2.7/dist-packages/rospy/topics.py", line 750, in _invoke_callback
    cb(msg)
  File "/mnt/data2/students/sub1/ccc_v1_w_OIyD_190740/asn329241_1/asn329242_1/work/catkin_ws/src/project1_solution/scripts/solution.py", line 8, in callback
    rospy.loginfo(data.a, data.b)
  File "/usr/lib/python2.7/logging/__init__.py", line 1167, in info
    self._log(INFO, msg, args, **kwargs)
  File "/usr/lib/python2.7/logging/__init__.py", line 1286, in _log
    self.handle(record)
  File "/usr/lib/python2.7/logging/__init__.py", line 1296, in handle
    self.callHandlers(record)
  File "/usr/lib/python2.7/logging/__init__.py", line 1336, in callHandlers
    hdlr.handle(record)
  File "/usr/lib/python2.7/logging/__init__.py", line 759, in handle
    self.emit(record)
  File "/opt/ros/kinetic/lib/python2.7/dist-packages/rosgraph/roslogging.py", line 182, in emit
    record_message = _defaultFormatter.format(record)
  File "/usr/lib/python2.7/logging/__init__.py", line 465, in format
    record.message = record.getMessage()
  File "/usr/lib/python2.7/logging/__init__.py", line 329, in getMessage
    msg = msg % self.args
TypeError: not all arguments converted during string formatting

[rosout][ERROR] 2021-02-12 16:38:20,856: bad callback: <function callback at 0x7f5e2807c5f0>
Traceback (most recent call last):
  File "/opt/ros/kinetic/lib/python2.7/dist-packages/rospy/topics.py", line 750, in _invoke_callback
    cb(msg)
  File "/mnt/data2/students/sub1/ccc_v1_w_OIyD_190740/asn329241_1/asn329242_1/work/catkin_ws/src/project1_solution/scripts/solution.py", line 8, in callback
    rospy.loginfo(data.a, data.b)
  File "/usr/lib/python2.7/logging/__init__.py", line 1167, in info
    self._log(INFO, msg, args, **kwargs)
  File "/usr/lib/python2.7/logging/__init__.py", line 1286, in _log
    self.handle(record)
  File "/usr/lib/python2.7/logging/__init__.py", line 1296, in handle
    self.callHandlers(record)
  File "/usr/lib/python2.7/logging/__init__.py", line 1336, in callHandlers
    hdlr.handle(record)
  File "/usr/lib/python2.7/logging/__init__.py", line 759, in handle
    self.emit(record)
  File "/opt/ros/kinetic/lib/python2.7/dist-packages/rosgraph/roslogging.py", line 182, in emit
    record_message = _defaultFormatter.format(record)
  File "/usr/lib/python2.7/logging/__init__.py", line 465, in format
    record.message = record.getMessage()
  File "/usr/lib/python2.7/logging/__init__.py", line 329, in getMessage
    msg = msg % self.args
TypeError: not all arguments converted during string formatting

[rosout][ERROR] 2021-02-12 16:38:22,856: bad callback: <function callback at 0x7f5e2807c5f0>
Traceback (most recent call last):
  File "/opt/ros/kinetic/lib/python2.7/dist-packages/rospy/topics.py", line 750, in _invoke_callback
    cb(msg)
  File "/mnt/data2/students/sub1/ccc_v1_w_OIyD_190740/asn329241_1/asn329242_1/work/catkin_ws/src/project1_solution/scripts/solution.py", line 8, in callback
    rospy.loginfo(data.a, data.b)
  File "/usr/lib/python2.7/logging/__init__.py", line 1167, in info
    self._log(INFO, msg, args, **kwargs)
  File "/usr/lib/python2.7/logging/__init__.py", line 1286, in _log
    self.handle(record)
  File "/usr/lib/python2.7/logging/__init__.py", line 1296, in handle
    self.callHandlers(record)
  File "/usr/lib/python2.7/logging/__init__.py", line 1336, in callHandlers
    hdlr.handle(record)
  File "/usr/lib/python2.7/logging/__init__.py", line 759, in handle
    self.emit(record)
  File "/opt/ros/kinetic/lib/python2.7/dist-packages/rosgraph/roslogging.py", line 182, in emit
    record_message = _defaultFormatter.format(record)
  File "/usr/lib/python2.7/logging/__init__.py", line 465, in format
    record.message = record.getMessage()
  File "/usr/lib/python2.7/logging/__init__.py", line 329, in getMessage
    msg = msg % self.args
TypeError: not all arguments converted during string formatting

[rosout][ERROR] 2021-02-12 16:38:24,855: bad callback: <function callback at 0x7f5e2807c5f0>
Traceback (most recent call last):
  File "/opt/ros/kinetic/lib/python2.7/dist-packages/rospy/topics.py", line 750, in _invoke_callback
    cb(msg)
  File "/mnt/data2/students/sub1/ccc_v1_w_OIyD_190740/asn329241_1/asn329242_1/work/catkin_ws/src/project1_solution/scripts/solution.py", line 8, in callback
    rospy.loginfo(data.a, data.b)
  File "/usr/lib/python2.7/logging/__init__.py", line 1167, in info
    self._log(INFO, msg, args, **kwargs)
  File "/usr/lib/python2.7/logging/__init__.py", line 1286, in _log
    self.handle(record)
  File "/usr/lib/python2.7/logging/__init__.py", line 1296, in handle
    self.callHandlers(record)
  File "/usr/lib/python2.7/logging/__init__.py", line 1336, in callHandlers
    hdlr.handle(record)
  File "/usr/lib/python2.7/logging/__init__.py", line 759, in handle
    self.emit(record)
  File "/opt/ros/kinetic/lib/python2.7/dist-packages/rosgraph/roslogging.py", line 182, in emit
    record_message = _defaultFormatter.format(record)
  File "/usr/lib/python2.7/logging/__init__.py", line 465, in format
    record.message = record.getMessage()
  File "/usr/lib/python2.7/logging/__init__.py", line 329, in getMessage
    msg = msg % self.args
TypeError: not all arguments converted during string formatting

[rosout][ERROR] 2021-02-12 16:38:26,855: bad callback: <function callback at 0x7f5e2807c5f0>
Traceback (most recent call last):
  File "/opt/ros/kinetic/lib/python2.7/dist-packages/rospy/topics.py", line 750, in _invoke_callback
    cb(msg)
  File "/mnt/data2/students/sub1/ccc_v1_w_OIyD_190740/asn329241_1/asn329242_1/work/catkin_ws/src/project1_solution/scripts/solution.py", line 8, in callback
    rospy.loginfo(data.a, data.b)
  File "/usr/lib/python2.7/logging/__init__.py", line 1167, in info
    self._log(INFO, msg, args, **kwargs)
  File "/usr/lib/python2.7/logging/__init__.py", line 1286, in _log
    self.handle(record)
  File "/usr/lib/python2.7/logging/__init__.py", line 1296, in handle
    self.callHandlers(record)
  File "/usr/lib/python2.7/logging/__init__.py", line 1336, in callHandlers
    hdlr.handle(record)
  File "/usr/lib/python2.7/logging/__init__.py", line 759, in handle
    self.emit(record)
  File "/opt/ros/kinetic/lib/python2.7/dist-packages/rosgraph/roslogging.py", line 182, in emit
    record_message = _defaultFormatter.format(record)
  File "/usr/lib/python2.7/logging/__init__.py", line 465, in format
    record.message = record.getMessage()
  File "/usr/lib/python2.7/logging/__init__.py", line 329, in getMessage
    msg = msg % self.args
TypeError: not all arguments converted during string formatting

[rosout][ERROR] 2021-02-12 16:38:28,854: bad callback: <function callback at 0x7f5e2807c5f0>
Traceback (most recent call last):
  File "/opt/ros/kinetic/lib/python2.7/dist-packages/rospy/topics.py", line 750, in _invoke_callback
    cb(msg)
  File "/mnt/data2/students/sub1/ccc_v1_w_OIyD_190740/asn329241_1/asn329242_1/work/catkin_ws/src/project1_solution/scripts/solution.py", line 8, in callback
    rospy.loginfo(data.a, data.b)
  File "/usr/lib/python2.7/logging/__init__.py", line 1167, in info
    self._log(INFO, msg, args, **kwargs)
  File "/usr/lib/python2.7/logging/__init__.py", line 1286, in _log
    self.handle(record)
  File "/usr/lib/python2.7/logging/__init__.py", line 1296, in handle
    self.callHandlers(record)
  File "/usr/lib/python2.7/logging/__init__.py", line 1336, in callHandlers
    hdlr.handle(record)
  File "/usr/lib/python2.7/logging/__init__.py", line 759, in handle
    self.emit(record)
  File "/opt/ros/kinetic/lib/python2.7/dist-packages/rosgraph/roslogging.py", line 182, in emit
    record_message = _defaultFormatter.format(record)
  File "/usr/lib/python2.7/logging/__init__.py", line 465, in format
    record.message = record.getMessage()
  File "/usr/lib/python2.7/logging/__init__.py", line 329, in getMessage
    msg = msg % self.args
TypeError: not all arguments converted during string formatting

[rosout][ERROR] 2021-02-12 16:38:30,855: bad callback: <function callback at 0x7f5e2807c5f0>
Traceback (most recent call last):
  File "/opt/ros/kinetic/lib/python2.7/dist-packages/rospy/topics.py", line 750, in _invoke_callback
    cb(msg)
  File "/mnt/data2/students/sub1/ccc_v1_w_OIyD_190740/asn329241_1/asn329242_1/work/catkin_ws/src/project1_solution/scripts/solution.py", line 8, in callback
    rospy.loginfo(data.a, data.b)
  File "/usr/lib/python2.7/logging/__init__.py", line 1167, in info
    self._log(INFO, msg, args, **kwargs)
  File "/usr/lib/python2.7/logging/__init__.py", line 1286, in _log
    self.handle(record)
  File "/usr/lib/python2.7/logging/__init__.py", line 1296, in handle
    self.callHandlers(record)
  File "/usr/lib/python2.7/logging/__init__.py", line 1336, in callHandlers
    hdlr.handle(record)
  File "/usr/lib/python2.7/logging/__init__.py", line 759, in handle
    self.emit(record)
  File "/opt/ros/kinetic/lib/python2.7/dist-packages/rosgraph/roslogging.py", line 182, in emit
    record_message = _defaultFormatter.format(record)
  File "/usr/lib/python2.7/logging/__init__.py", line 465, in format
    record.message = record.getMessage()
  File "/usr/lib/python2.7/logging/__init__.py", line 329, in getMessage
    msg = msg % self.args
TypeError: not all arguments converted during string formatting

[rosout][ERROR] 2021-02-12 16:38:32,856: bad callback: <function callback at 0x7f5e2807c5f0>
Traceback (most recent call last):
  File "/opt/ros/kinetic/lib/python2.7/dist-packages/rospy/topics.py", line 750, in _invoke_callback
    cb(msg)
  File "/mnt/data2/students/sub1/ccc_v1_w_OIyD_190740/asn329241_1/asn329242_1/work/catkin_ws/src/project1_solution/scripts/solution.py", line 8, in callback
    rospy.loginfo(data.a, data.b)
  File "/usr/lib/python2.7/logging/__init__.py", line 1167, in info
    self._log(INFO, msg, args, **kwargs)
  File "/usr/lib/python2.7/logging/__init__.py", line 1286, in _log
    self.handle(record)
  File "/usr/lib/python2.7/logging/__init__.py", line 1296, in handle
    self.callHandlers(record)
  File "/usr/lib/python2.7/logging/__init__.py", line 1336, in callHandlers
    hdlr.handle(record)
  File "/usr/lib/python2.7/logging/__init__.py", line 759, in handle
    self.emit(record)
  File "/opt/ros/kinetic/lib/python2.7/dist-packages/rosgraph/roslogging.py", line 182, in emit
    record_message = _defaultFormatter.format(record)
  File "/usr/lib/python2.7/logging/__init__.py", line 465, in format
    record.message = record.getMessage()
  File "/usr/lib/python2.7/logging/__init__.py", line 329, in getMessage
    msg = msg % self.args
TypeError: not all arguments converted during string formatting

[rosout][ERROR] 2021-02-12 16:38:34,856: bad callback: <function callback at 0x7f5e2807c5f0>
Traceback (most recent call last):
  File "/opt/ros/kinetic/lib/python2.7/dist-packages/rospy/topics.py", line 750, in _invoke_callback
    cb(msg)
  File "/mnt/data2/students/sub1/ccc_v1_w_OIyD_190740/asn329241_1/asn329242_1/work/catkin_ws/src/project1_solution/scripts/solution.py", line 8, in callback
    rospy.loginfo(data.a, data.b)
  File "/usr/lib/python2.7/logging/__init__.py", line 1167, in info
    self._log(INFO, msg, args, **kwargs)
  File "/usr/lib/python2.7/logging/__init__.py", line 1286, in _log
    self.handle(record)
  File "/usr/lib/python2.7/logging/__init__.py", line 1296, in handle
    self.callHandlers(record)
  File "/usr/lib/python2.7/logging/__init__.py", line 1336, in callHandlers
    hdlr.handle(record)
  File "/usr/lib/python2.7/logging/__init__.py", line 759, in handle
    self.emit(record)
  File "/opt/ros/kinetic/lib/python2.7/dist-packages/rosgraph/roslogging.py", line 182, in emit
    record_message = _defaultFormatter.format(record)
  File "/usr/lib/python2.7/logging/__init__.py", line 465, in format
    record.message = record.getMessage()
  File "/usr/lib/python2.7/logging/__init__.py", line 329, in getMessage
    msg = msg % self.args
TypeError: not all arguments converted during string formatting

[rosout][ERROR] 2021-02-12 16:38:36,854: bad callback: <function callback at 0x7f5e2807c5f0>
Traceback (most recent call last):
  File "/opt/ros/kinetic/lib/python2.7/dist-packages/rospy/topics.py", line 750, in _invoke_callback
    cb(msg)
  File "/mnt/data2/students/sub1/ccc_v1_w_OIyD_190740/asn329241_1/asn329242_1/work/catkin_ws/src/project1_solution/scripts/solution.py", line 8, in callback
    rospy.loginfo(data.a, data.b)
  File "/usr/lib/python2.7/logging/__init__.py", line 1167, in info
    self._log(INFO, msg, args, **kwargs)
  File "/usr/lib/python2.7/logging/__init__.py", line 1286, in _log
    self.handle(record)
  File "/usr/lib/python2.7/logging/__init__.py", line 1296, in handle
    self.callHandlers(record)
  File "/usr/lib/python2.7/logging/__init__.py", line 1336, in callHandlers
    hdlr.handle(record)
  File "/usr/lib/python2.7/logging/__init__.py", line 759, in handle
    self.emit(record)
  File "/opt/ros/kinetic/lib/python2.7/dist-packages/rosgraph/roslogging.py", line 182, in emit
    record_message = _defaultFormatter.format(record)
  File "/usr/lib/python2.7/logging/__init__.py", line 465, in format
    record.message = record.getMessage()
  File "/usr/lib/python2.7/logging/__init__.py", line 329, in getMessage
    msg = msg % self.args
TypeError: not all arguments converted during string formatting

[rosout][ERROR] 2021-02-12 16:38:38,855: bad callback: <function callback at 0x7f5e2807c5f0>
Traceback (most recent call last):
  File "/opt/ros/kinetic/lib/python2.7/dist-packages/rospy/topics.py", line 750, in _invoke_callback
    cb(msg)
  File "/mnt/data2/students/sub1/ccc_v1_w_OIyD_190740/asn329241_1/asn329242_1/work/catkin_ws/src/project1_solution/scripts/solution.py", line 8, in callback
    rospy.loginfo(data.a, data.b)
  File "/usr/lib/python2.7/logging/__init__.py", line 1167, in info
    self._log(INFO, msg, args, **kwargs)
  File "/usr/lib/python2.7/logging/__init__.py", line 1286, in _log
    self.handle(record)
  File "/usr/lib/python2.7/logging/__init__.py", line 1296, in handle
    self.callHandlers(record)
  File "/usr/lib/python2.7/logging/__init__.py", line 1336, in callHandlers
    hdlr.handle(record)
  File "/usr/lib/python2.7/logging/__init__.py", line 759, in handle
    self.emit(record)
  File "/opt/ros/kinetic/lib/python2.7/dist-packages/rosgraph/roslogging.py", line 182, in emit
    record_message = _defaultFormatter.format(record)
  File "/usr/lib/python2.7/logging/__init__.py", line 465, in format
    record.message = record.getMessage()
  File "/usr/lib/python2.7/logging/__init__.py", line 329, in getMessage
    msg = msg % self.args
TypeError: not all arguments converted during string formatting

[rosout][ERROR] 2021-02-12 16:38:40,855: bad callback: <function callback at 0x7f5e2807c5f0>
Traceback (most recent call last):
  File "/opt/ros/kinetic/lib/python2.7/dist-packages/rospy/topics.py", line 750, in _invoke_callback
    cb(msg)
  File "/mnt/data2/students/sub1/ccc_v1_w_OIyD_190740/asn329241_1/asn329242_1/work/catkin_ws/src/project1_solution/scripts/solution.py", line 8, in callback
    rospy.loginfo(data.a, data.b)
  File "/usr/lib/python2.7/logging/__init__.py", line 1167, in info
    self._log(INFO, msg, args, **kwargs)
  File "/usr/lib/python2.7/logging/__init__.py", line 1286, in _log
    self.handle(record)
  File "/usr/lib/python2.7/logging/__init__.py", line 1296, in handle
    self.callHandlers(record)
  File "/usr/lib/python2.7/logging/__init__.py", line 1336, in callHandlers
    hdlr.handle(record)
  File "/usr/lib/python2.7/logging/__init__.py", line 759, in handle
    self.emit(record)
  File "/opt/ros/kinetic/lib/python2.7/dist-packages/rosgraph/roslogging.py", line 182, in emit
    record_message = _defaultFormatter.format(record)
  File "/usr/lib/python2.7/logging/__init__.py", line 465, in format
    record.message = record.getMessage()
  File "/usr/lib/python2.7/logging/__init__.py", line 329, in getMessage
    msg = msg % self.args
TypeError: not all arguments converted during string formatting

[rosout][ERROR] 2021-02-12 16:38:42,857: bad callback: <function callback at 0x7f5e2807c5f0>
Traceback (most recent call last):
  File "/opt/ros/kinetic/lib/python2.7/dist-packages/rospy/topics.py", line 750, in _invoke_callback
    cb(msg)
  File "/mnt/data2/students/sub1/ccc_v1_w_OIyD_190740/asn329241_1/asn329242_1/work/catkin_ws/src/project1_solution/scripts/solution.py", line 8, in callback
    rospy.loginfo(data[0])
  File "/usr/lib/python2.7/logging/__init__.py", line 1167, in info
    self._log(INFO, msg, args, **kwargs)
  File "/usr/lib/python2.7/logging/__init__.py", line 1286, in _log
    self.handle(record)
  File "/usr/lib/python2.7/logging/__init__.py", line 1296, in handle
    self.callHandlers(record)
  File "/usr/lib/python2.7/logging/__init__.py", line 1336, in callHandlers
    hdlr.handle(record)
  File "/usr/lib/python2.7/logging/__init__.py", line 759, in handle
    self.emit(record)
  File "/opt/ros/kinetic/lib/python2.7/dist-packages/rosgraph/roslogging.py", line 182, in emit
    record_message = _defaultFormatter.format(record)
  File "/usr/lib/python2.7/logging/__init__.py", line 465, in format
    record.message = record.getMessage()
  File "/usr/lib/python2.7/logging/__init__.py", line 329, in getMessage
    msg = msg % self.args
TypeError: not all arguments converted during string formatting

[rospy.core][INFO] 2021-02-12 16:38:43,523: signal_shutdown [signal-2]
[rospy.internal][INFO] 2021-02-12 16:38:43,549: topic[/rosout] removing connection to /rosout
[rospy.internal][INFO] 2021-02-12 16:38:43,555: topic[/two_ints] removing connection to http://ip-172-31-17-9:43152/
[rospy.impl.masterslave][INFO] 2021-02-12 16:38:43,559: signal-2
[rospy.core][INFO] 2021-02-12 16:38:43,670: signal_shutdown [atexit]
[rospy.client][INFO] 2021-02-12 16:38:46,059: init_node, name[/solution], pid[17900]
[xmlrpc][INFO] 2021-02-12 16:38:46,060: XML-RPC server binding to 0.0.0.0:0
[xmlrpc][INFO] 2021-02-12 16:38:46,127: Started XML-RPC server [http://ip-172-31-17-9:39048/]
[rospy.init][INFO] 2021-02-12 16:38:46,128: ROS Slave URI: [http://ip-172-31-17-9:39048/]
[rospy.impl.masterslave][INFO] 2021-02-12 16:38:46,142: _ready: http://ip-172-31-17-9:39048/
[xmlrpc][INFO] 2021-02-12 16:38:46,151: xml rpc node: starting XML-RPC server
[rospy.registration][INFO] 2021-02-12 16:38:46,152: Registering with master node http://localhost:40963
[rospy.init][INFO] 2021-02-12 16:38:46,247: registered with master
[rospy.rosout][INFO] 2021-02-12 16:38:46,255: initializing /rosout core topic
[rospy.rosout][INFO] 2021-02-12 16:38:46,264: connected to core topic /rosout
[rospy.simtime][INFO] 2021-02-12 16:38:46,271: /use_sim_time is not set, will not subscribe to simulated time [/clock] topic
[rospy.internal][INFO] 2021-02-12 16:38:46,331: topic[/two_ints] adding connection to [http://ip-172-31-17-9:43152/], count 0
[rospy.internal][INFO] 2021-02-12 16:38:46,510: topic[/rosout] adding connection to [/rosout], count 0
[rosout][ERROR] 2021-02-12 16:38:46,854: bad callback: <function callback at 0x7fdd6f2ff5f0>
Traceback (most recent call last):
  File "/opt/ros/kinetic/lib/python2.7/dist-packages/rospy/topics.py", line 750, in _invoke_callback
    cb(msg)
  File "/mnt/data2/students/sub1/ccc_v1_w_OIyD_190740/asn329241_1/asn329242_1/work/catkin_ws/src/project1_solution/scripts/solution.py", line 8, in callback
    rospy.loginfo(data[0])
TypeError: 'TwoInts' object does not support indexing

[rosout][ERROR] 2021-02-12 16:38:48,856: bad callback: <function callback at 0x7fdd6f2ff5f0>
Traceback (most recent call last):
  File "/opt/ros/kinetic/lib/python2.7/dist-packages/rospy/topics.py", line 750, in _invoke_callback
    cb(msg)
  File "/mnt/data2/students/sub1/ccc_v1_w_OIyD_190740/asn329241_1/asn329242_1/work/catkin_ws/src/project1_solution/scripts/solution.py", line 8, in callback
    rospy.loginfo(data[0])
TypeError: 'TwoInts' object does not support indexing

[rosout][ERROR] 2021-02-12 16:38:50,855: bad callback: <function callback at 0x7fdd6f2ff5f0>
Traceback (most recent call last):
  File "/opt/ros/kinetic/lib/python2.7/dist-packages/rospy/topics.py", line 750, in _invoke_callback
    cb(msg)
  File "/mnt/data2/students/sub1/ccc_v1_w_OIyD_190740/asn329241_1/asn329242_1/work/catkin_ws/src/project1_solution/scripts/solution.py", line 8, in callback
    rospy.loginfo(data[0])
TypeError: 'TwoInts' object does not support indexing

[rospy.core][INFO] 2021-02-12 16:38:52,637: signal_shutdown [signal-2]
[rospy.internal][INFO] 2021-02-12 16:38:52,658: topic[/rosout] removing connection to /rosout
[rospy.internal][INFO] 2021-02-12 16:38:52,662: topic[/two_ints] removing connection to http://ip-172-31-17-9:43152/
[rospy.internal][WARNING] 2021-02-12 16:38:52,662: Unknown error initiating TCP/IP socket to ip-172-31-17-9:46199 (http://ip-172-31-17-9:43152/): Traceback (most recent call last):
  File "/opt/ros/kinetic/lib/python2.7/dist-packages/rospy/impl/tcpros_base.py", line 557, in connect
    self.read_header()
  File "/opt/ros/kinetic/lib/python2.7/dist-packages/rospy/impl/tcpros_base.py", line 650, in read_header
    self._validate_header(read_ros_handshake_header(sock, self.read_buff, self.protocol.buff_size))
AttributeError: 'NoneType' object has no attribute 'buff_size'

[rospy.topics][ERROR] 2021-02-12 16:38:52,666: Traceback (most recent call last):
  File "/opt/ros/kinetic/lib/python2.7/dist-packages/rospy/topics.py", line 326, in close
    c.close()
  File "/opt/ros/kinetic/lib/python2.7/dist-packages/rospy/impl/tcpros_base.py", line 838, in close
    self.socket.close()
AttributeError: 'NoneType' object has no attribute 'close'

[rospy.impl.masterslave][INFO] 2021-02-12 16:38:52,673: signal-2
[rospy.core][INFO] 2021-02-12 16:38:53,291: signal_shutdown [atexit]
[rospy.client][INFO] 2021-02-12 16:41:31,074: init_node, name[/solution], pid[21144]
[xmlrpc][INFO] 2021-02-12 16:41:31,074: XML-RPC server binding to 0.0.0.0:0
[xmlrpc][INFO] 2021-02-12 16:41:31,078: Started XML-RPC server [http://ip-172-31-17-9:34186/]
[rospy.init][INFO] 2021-02-12 16:41:31,078: ROS Slave URI: [http://ip-172-31-17-9:34186/]
[rospy.impl.masterslave][INFO] 2021-02-12 16:41:31,082: _ready: http://ip-172-31-17-9:34186/
[rospy.registration][INFO] 2021-02-12 16:41:31,097: Registering with master node http://localhost:40963
[xmlrpc][INFO] 2021-02-12 16:41:31,097: xml rpc node: starting XML-RPC server
[rospy.init][INFO] 2021-02-12 16:41:31,192: registered with master
[rospy.rosout][INFO] 2021-02-12 16:41:31,207: initializing /rosout core topic
[rospy.rosout][INFO] 2021-02-12 16:41:31,224: connected to core topic /rosout
[rospy.simtime][INFO] 2021-02-12 16:41:31,233: /use_sim_time is not set, will not subscribe to simulated time [/clock] topic
[rospy.internal][INFO] 2021-02-12 16:41:31,266: topic[/two_ints] adding connection to [http://ip-172-31-17-9:43152/], count 0
[rospy.internal][INFO] 2021-02-12 16:41:31,440: topic[/rosout] adding connection to [/rosout], count 0
[rosout][ERROR] 2021-02-12 16:41:32,856: bad callback: <function callback at 0x7f9923ec85f0>
Traceback (most recent call last):
  File "/opt/ros/kinetic/lib/python2.7/dist-packages/rospy/topics.py", line 750, in _invoke_callback
    cb(msg)
  File "/mnt/data2/students/sub1/ccc_v1_w_OIyD_190740/asn329241_1/asn329242_1/work/catkin_ws/src/project1_solution/scripts/solution.py", line 8, in callback
    rospy.loginfo(data[a])
NameError: global name 'a' is not defined

[rosout][ERROR] 2021-02-12 16:41:34,855: bad callback: <function callback at 0x7f9923ec85f0>
Traceback (most recent call last):
  File "/opt/ros/kinetic/lib/python2.7/dist-packages/rospy/topics.py", line 750, in _invoke_callback
    cb(msg)
  File "/mnt/data2/students/sub1/ccc_v1_w_OIyD_190740/asn329241_1/asn329242_1/work/catkin_ws/src/project1_solution/scripts/solution.py", line 8, in callback
    rospy.loginfo(data[a])
NameError: global name 'a' is not defined

[rospy.core][INFO] 2021-02-12 16:41:36,829: signal_shutdown [signal-2]
[rospy.internal][INFO] 2021-02-12 16:41:36,850: topic[/rosout] removing connection to /rosout
[rospy.internal][INFO] 2021-02-12 16:41:36,855: topic[/two_ints] removing connection to http://ip-172-31-17-9:43152/
[rospy.impl.masterslave][INFO] 2021-02-12 16:41:36,859: signal-2
[rospy.core][INFO] 2021-02-12 16:41:36,994: signal_shutdown [atexit]
[rospy.client][INFO] 2021-02-12 16:41:55,523: init_node, name[/solution], pid[21826]
[xmlrpc][INFO] 2021-02-12 16:41:55,523: XML-RPC server binding to 0.0.0.0:0
[xmlrpc][INFO] 2021-02-12 16:41:55,528: Started XML-RPC server [http://ip-172-31-17-9:37433/]
[rospy.init][INFO] 2021-02-12 16:41:55,529: ROS Slave URI: [http://ip-172-31-17-9:37433/]
[rospy.impl.masterslave][INFO] 2021-02-12 16:41:55,531: _ready: http://ip-172-31-17-9:37433/
[xmlrpc][INFO] 2021-02-12 16:41:55,548: xml rpc node: starting XML-RPC server
[rospy.registration][INFO] 2021-02-12 16:41:55,548: Registering with master node http://localhost:40963
[rospy.init][INFO] 2021-02-12 16:41:55,642: registered with master
[rospy.rosout][INFO] 2021-02-12 16:41:55,647: initializing /rosout core topic
[rospy.rosout][INFO] 2021-02-12 16:41:55,655: connected to core topic /rosout
[rospy.simtime][INFO] 2021-02-12 16:41:55,662: /use_sim_time is not set, will not subscribe to simulated time [/clock] topic
[rospy.internal][INFO] 2021-02-12 16:41:55,722: topic[/two_ints] adding connection to [http://ip-172-31-17-9:43152/], count 0
[rospy.internal][INFO] 2021-02-12 16:41:55,873: topic[/rosout] adding connection to [/rosout], count 0
[rosout][ERROR] 2021-02-12 16:41:56,856: bad callback: <function callback at 0x7f71e371f5f0>
Traceback (most recent call last):
  File "/opt/ros/kinetic/lib/python2.7/dist-packages/rospy/topics.py", line 750, in _invoke_callback
    cb(msg)
  File "/mnt/data2/students/sub1/ccc_v1_w_OIyD_190740/asn329241_1/asn329242_1/work/catkin_ws/src/project1_solution/scripts/solution.py", line 8, in callback
    rospy.loginfo(data['a'])
TypeError: 'TwoInts' object has no attribute '__getitem__'

[rosout][ERROR] 2021-02-12 16:41:58,856: bad callback: <function callback at 0x7f71e371f5f0>
Traceback (most recent call last):
  File "/opt/ros/kinetic/lib/python2.7/dist-packages/rospy/topics.py", line 750, in _invoke_callback
    cb(msg)
  File "/mnt/data2/students/sub1/ccc_v1_w_OIyD_190740/asn329241_1/asn329242_1/work/catkin_ws/src/project1_solution/scripts/solution.py", line 8, in callback
    rospy.loginfo(data['a'])
TypeError: 'TwoInts' object has no attribute '__getitem__'

[rosout][ERROR] 2021-02-12 16:42:00,857: bad callback: <function callback at 0x7f71e371f5f0>
Traceback (most recent call last):
  File "/opt/ros/kinetic/lib/python2.7/dist-packages/rospy/topics.py", line 750, in _invoke_callback
    cb(msg)
  File "/mnt/data2/students/sub1/ccc_v1_w_OIyD_190740/asn329241_1/asn329242_1/work/catkin_ws/src/project1_solution/scripts/solution.py", line 8, in callback
    rospy.loginfo(data['a'])
TypeError: 'TwoInts' object has no attribute '__getitem__'

[rospy.core][INFO] 2021-02-12 16:42:02,216: signal_shutdown [signal-2]
[rospy.internal][INFO] 2021-02-12 16:42:02,239: topic[/rosout] removing connection to /rosout
[rospy.internal][INFO] 2021-02-12 16:42:02,243: topic[/two_ints] removing connection to http://ip-172-31-17-9:43152/
[rospy.internal][WARNING] 2021-02-12 16:42:02,244: Unknown error initiating TCP/IP socket to ip-172-31-17-9:46199 (http://ip-172-31-17-9:43152/): Traceback (most recent call last):
  File "/opt/ros/kinetic/lib/python2.7/dist-packages/rospy/impl/tcpros_base.py", line 557, in connect
    self.read_header()
  File "/opt/ros/kinetic/lib/python2.7/dist-packages/rospy/impl/tcpros_base.py", line 650, in read_header
    self._validate_header(read_ros_handshake_header(sock, self.read_buff, self.protocol.buff_size))
AttributeError: 'NoneType' object has no attribute 'buff_size'

[rospy.topics][ERROR] 2021-02-12 16:42:02,249: Traceback (most recent call last):
  File "/opt/ros/kinetic/lib/python2.7/dist-packages/rospy/topics.py", line 326, in close
    c.close()
  File "/opt/ros/kinetic/lib/python2.7/dist-packages/rospy/impl/tcpros_base.py", line 838, in close
    self.socket.close()
AttributeError: 'NoneType' object has no attribute 'close'

[rospy.impl.masterslave][INFO] 2021-02-12 16:42:02,259: signal-2
[rospy.core][INFO] 2021-02-12 16:42:02,829: signal_shutdown [atexit]
[rospy.client][INFO] 2021-02-12 16:44:00,933: init_node, name[/solution], pid[25095]
[xmlrpc][INFO] 2021-02-12 16:44:00,933: XML-RPC server binding to 0.0.0.0:0
[xmlrpc][INFO] 2021-02-12 16:44:00,937: Started XML-RPC server [http://ip-172-31-17-9:41529/]
[rospy.init][INFO] 2021-02-12 16:44:00,937: ROS Slave URI: [http://ip-172-31-17-9:41529/]
[rospy.impl.masterslave][INFO] 2021-02-12 16:44:00,943: _ready: http://ip-172-31-17-9:41529/
[xmlrpc][INFO] 2021-02-12 16:44:00,951: xml rpc node: starting XML-RPC server
[rospy.registration][INFO] 2021-02-12 16:44:00,951: Registering with master node http://localhost:40963
[rospy.init][INFO] 2021-02-12 16:44:01,047: registered with master
[rospy.rosout][INFO] 2021-02-12 16:44:01,052: initializing /rosout core topic
[rospy.rosout][INFO] 2021-02-12 16:44:01,058: connected to core topic /rosout
[rospy.simtime][INFO] 2021-02-12 16:44:01,064: /use_sim_time is not set, will not subscribe to simulated time [/clock] topic
[rospy.internal][INFO] 2021-02-12 16:44:01,124: topic[/two_ints] adding connection to [http://ip-172-31-17-9:43152/], count 0
[rospy.internal][INFO] 2021-02-12 16:44:01,350: topic[/rosout] adding connection to [/rosout], count 0
[rosout][INFO] 2021-02-12 16:44:02,855: 3
[rosout][INFO] 2021-02-12 16:44:04,855: 19
[rosout][INFO] 2021-02-12 16:44:06,854: 7
[rospy.core][INFO] 2021-02-12 16:44:07,219: signal_shutdown [signal-2]
[rospy.internal][INFO] 2021-02-12 16:44:07,241: topic[/rosout] removing connection to /rosout
[rospy.internal][INFO] 2021-02-12 16:44:07,245: topic[/two_ints] removing connection to http://ip-172-31-17-9:43152/
[rospy.internal][WARNING] 2021-02-12 16:44:07,246: Unknown error initiating TCP/IP socket to ip-172-31-17-9:46199 (http://ip-172-31-17-9:43152/): Traceback (most recent call last):
  File "/opt/ros/kinetic/lib/python2.7/dist-packages/rospy/impl/tcpros_base.py", line 557, in connect
    self.read_header()
  File "/opt/ros/kinetic/lib/python2.7/dist-packages/rospy/impl/tcpros_base.py", line 650, in read_header
    self._validate_header(read_ros_handshake_header(sock, self.read_buff, self.protocol.buff_size))
AttributeError: 'NoneType' object has no attribute 'buff_size'

[rospy.topics][ERROR] 2021-02-12 16:44:07,249: Traceback (most recent call last):
  File "/opt/ros/kinetic/lib/python2.7/dist-packages/rospy/topics.py", line 326, in close
    c.close()
  File "/opt/ros/kinetic/lib/python2.7/dist-packages/rospy/impl/tcpros_base.py", line 838, in close
    self.socket.close()
AttributeError: 'NoneType' object has no attribute 'close'

[rospy.impl.masterslave][INFO] 2021-02-12 16:44:07,256: signal-2
[rospy.core][INFO] 2021-02-12 16:44:07,875: signal_shutdown [atexit]
[rospy.client][INFO] 2021-02-12 16:47:40,548: init_node, name[/solution], pid[27480]
[xmlrpc][INFO] 2021-02-12 16:47:40,548: XML-RPC server binding to 0.0.0.0:0
[xmlrpc][INFO] 2021-02-12 16:47:40,552: Started XML-RPC server [http://ip-172-31-17-9:42108/]
[rospy.init][INFO] 2021-02-12 16:47:40,552: ROS Slave URI: [http://ip-172-31-17-9:42108/]
[rospy.impl.masterslave][INFO] 2021-02-12 16:47:40,556: _ready: http://ip-172-31-17-9:42108/
[xmlrpc][INFO] 2021-02-12 16:47:40,563: xml rpc node: starting XML-RPC server
[rospy.registration][INFO] 2021-02-12 16:47:40,563: Registering with master node http://localhost:40963
[rospy.init][INFO] 2021-02-12 16:47:40,659: registered with master
[rospy.rosout][INFO] 2021-02-12 16:47:40,663: initializing /rosout core topic
[rospy.rosout][INFO] 2021-02-12 16:47:40,670: connected to core topic /rosout
[rospy.simtime][INFO] 2021-02-12 16:47:40,676: /use_sim_time is not set, will not subscribe to simulated time [/clock] topic
[rospy.internal][INFO] 2021-02-12 16:47:40,735: topic[/two_ints] adding connection to [http://ip-172-31-17-9:43152/], count 0
[rosout][INFO] 2021-02-12 16:47:40,854: a: 18
b: 2
[rosout][ERROR] 2021-02-12 16:47:40,865: bad callback: <function callback at 0x7f9f530635f0>
Traceback (most recent call last):
  File "/opt/ros/kinetic/lib/python2.7/dist-packages/rospy/topics.py", line 750, in _invoke_callback
    cb(msg)
  File "/mnt/data2/students/sub1/ccc_v1_w_OIyD_190740/asn329241_1/asn329242_1/work/catkin_ws/src/project1_solution/scripts/solution.py", line 10, in callback
    rospy.init_node('talker', anonymous=True)
  File "/opt/ros/kinetic/lib/python2.7/dist-packages/rospy/client.py", line 274, in init_node
    raise rospy.exceptions.ROSException("rospy.init_node() has already been called with different arguments: "+str(_init_node_args))
ROSException: rospy.init_node() has already been called with different arguments: ('solution', ['/mnt/data2/students/sub1/ccc_v1_w_OIyD_190740/asn329241_1/asn329242_1/work/catkin_ws/src/project1_solution/scripts/solution.py'], False, None, False, False)

[rospy.internal][INFO] 2021-02-12 16:47:40,925: topic[/rosout] adding connection to [/rosout], count 0
[rospy.internal][INFO] 2021-02-12 16:47:40,950: topic[/two_ints] adding connection to [http://ip-172-31-17-9:42108/], count 1
[rosout][WARNING] 2021-02-12 16:47:40,954: Could not process inbound connection: topic types do not match: [project1_solution/TwoInts] vs. [std_msgs/Int16]{'message_definition': 'int16 a\nint16 b', 'callerid': '/solution', 'tcp_nodelay': '0', 'md5sum': 'e01e889cb1a7965611513515df5899bf', 'topic': '/two_ints', 'type': 'project1_solution/TwoInts'}
[rospy.internal][ERROR] 2021-02-12 16:47:40,955: Unable to initiate TCP/IP socket to ip-172-31-17-9:44197 (http://ip-172-31-17-9:42108/): Traceback (most recent call last):
  File "/opt/ros/kinetic/lib/python2.7/dist-packages/rospy/impl/tcpros_base.py", line 557, in connect
    self.read_header()
  File "/opt/ros/kinetic/lib/python2.7/dist-packages/rospy/impl/tcpros_base.py", line 650, in read_header
    self._validate_header(read_ros_handshake_header(sock, self.read_buff, self.protocol.buff_size))
  File "/opt/ros/kinetic/lib/python2.7/dist-packages/rospy/impl/tcpros_base.py", line 593, in _validate_header
    raise TransportInitError("remote error reported: %s"%header['error'])
TransportInitError: remote error reported: topic types do not match: [project1_solution/TwoInts] vs. [std_msgs/Int16]

[rospy.internal][ERROR] 2021-02-12 16:47:40,963: unable to create subscriber transport: remote error reported: topic types do not match: [project1_solution/TwoInts] vs. [std_msgs/Int16].  Will try again in 0.5s
[rosout][WARNING] 2021-02-12 16:47:41,970: Could not process inbound connection: topic types do not match: [project1_solution/TwoInts] vs. [std_msgs/Int16]{'message_definition': 'int16 a\nint16 b', 'callerid': '/solution', 'tcp_nodelay': '0', 'md5sum': 'e01e889cb1a7965611513515df5899bf', 'topic': '/two_ints', 'type': 'project1_solution/TwoInts'}
[rospy.internal][ERROR] 2021-02-12 16:47:41,971: Unable to initiate TCP/IP socket to ip-172-31-17-9:44197 (http://ip-172-31-17-9:42108/): Traceback (most recent call last):
  File "/opt/ros/kinetic/lib/python2.7/dist-packages/rospy/impl/tcpros_base.py", line 557, in connect
    self.read_header()
  File "/opt/ros/kinetic/lib/python2.7/dist-packages/rospy/impl/tcpros_base.py", line 650, in read_header
    self._validate_header(read_ros_handshake_header(sock, self.read_buff, self.protocol.buff_size))
  File "/opt/ros/kinetic/lib/python2.7/dist-packages/rospy/impl/tcpros_base.py", line 593, in _validate_header
    raise TransportInitError("remote error reported: %s"%header['error'])
TransportInitError: remote error reported: topic types do not match: [project1_solution/TwoInts] vs. [std_msgs/Int16]

[rosout][INFO] 2021-02-12 16:47:42,854: a: 10
b: 16
[rosout][ERROR] 2021-02-12 16:47:42,858: bad callback: <function callback at 0x7f9f530635f0>
Traceback (most recent call last):
  File "/opt/ros/kinetic/lib/python2.7/dist-packages/rospy/topics.py", line 750, in _invoke_callback
    cb(msg)
  File "/mnt/data2/students/sub1/ccc_v1_w_OIyD_190740/asn329241_1/asn329242_1/work/catkin_ws/src/project1_solution/scripts/solution.py", line 10, in callback
    rospy.init_node('talker', anonymous=True)
  File "/opt/ros/kinetic/lib/python2.7/dist-packages/rospy/client.py", line 274, in init_node
    raise rospy.exceptions.ROSException("rospy.init_node() has already been called with different arguments: "+str(_init_node_args))
ROSException: rospy.init_node() has already been called with different arguments: ('solution', ['/mnt/data2/students/sub1/ccc_v1_w_OIyD_190740/asn329241_1/asn329242_1/work/catkin_ws/src/project1_solution/scripts/solution.py'], False, None, False, False)

[rosout][WARNING] 2021-02-12 16:47:42,981: Could not process inbound connection: topic types do not match: [project1_solution/TwoInts] vs. [std_msgs/Int16]{'message_definition': 'int16 a\nint16 b', 'callerid': '/solution', 'tcp_nodelay': '0', 'md5sum': 'e01e889cb1a7965611513515df5899bf', 'topic': '/two_ints', 'type': 'project1_solution/TwoInts'}
[rospy.internal][ERROR] 2021-02-12 16:47:42,982: Unable to initiate TCP/IP socket to ip-172-31-17-9:44197 (http://ip-172-31-17-9:42108/): Traceback (most recent call last):
  File "/opt/ros/kinetic/lib/python2.7/dist-packages/rospy/impl/tcpros_base.py", line 557, in connect
    self.read_header()
  File "/opt/ros/kinetic/lib/python2.7/dist-packages/rospy/impl/tcpros_base.py", line 650, in read_header
    self._validate_header(read_ros_handshake_header(sock, self.read_buff, self.protocol.buff_size))
  File "/opt/ros/kinetic/lib/python2.7/dist-packages/rospy/impl/tcpros_base.py", line 593, in _validate_header
    raise TransportInitError("remote error reported: %s"%header['error'])
TransportInitError: remote error reported: topic types do not match: [project1_solution/TwoInts] vs. [std_msgs/Int16]

[rosout][INFO] 2021-02-12 16:47:44,854: a: 17
b: 2
[rosout][ERROR] 2021-02-12 16:47:44,859: bad callback: <function callback at 0x7f9f530635f0>
Traceback (most recent call last):
  File "/opt/ros/kinetic/lib/python2.7/dist-packages/rospy/topics.py", line 750, in _invoke_callback
    cb(msg)
  File "/mnt/data2/students/sub1/ccc_v1_w_OIyD_190740/asn329241_1/asn329242_1/work/catkin_ws/src/project1_solution/scripts/solution.py", line 10, in callback
    rospy.init_node('talker', anonymous=True)
  File "/opt/ros/kinetic/lib/python2.7/dist-packages/rospy/client.py", line 274, in init_node
    raise rospy.exceptions.ROSException("rospy.init_node() has already been called with different arguments: "+str(_init_node_args))
ROSException: rospy.init_node() has already been called with different arguments: ('solution', ['/mnt/data2/students/sub1/ccc_v1_w_OIyD_190740/asn329241_1/asn329242_1/work/catkin_ws/src/project1_solution/scripts/solution.py'], False, None, False, False)

[rospy.internal][ERROR] 2021-02-12 16:47:44,991: Unable to initiate TCP/IP socket to ip-172-31-17-9:44197 (http://ip-172-31-17-9:42108/): Traceback (most recent call last):
  File "/opt/ros/kinetic/lib/python2.7/dist-packages/rospy/impl/tcpros_base.py", line 557, in connect
    self.read_header()
  File "/opt/ros/kinetic/lib/python2.7/dist-packages/rospy/impl/tcpros_base.py", line 650, in read_header
    self._validate_header(read_ros_handshake_header(sock, self.read_buff, self.protocol.buff_size))
  File "/opt/ros/kinetic/lib/python2.7/dist-packages/rospy/impl/tcpros_base.py", line 593, in _validate_header
    raise TransportInitError("remote error reported: %s"%header['error'])
TransportInitError: remote error reported: topic types do not match: [project1_solution/TwoInts] vs. [std_msgs/Int16]

[rosout][WARNING] 2021-02-12 16:47:44,990: Could not process inbound connection: topic types do not match: [project1_solution/TwoInts] vs. [std_msgs/Int16]{'message_definition': 'int16 a\nint16 b', 'callerid': '/solution', 'tcp_nodelay': '0', 'md5sum': 'e01e889cb1a7965611513515df5899bf', 'topic': '/two_ints', 'type': 'project1_solution/TwoInts'}
[rospy.core][INFO] 2021-02-12 16:47:46,101: signal_shutdown [signal-2]
[rospy.internal][INFO] 2021-02-12 16:47:46,125: topic[/rosout] removing connection to /rosout
[rospy.internal][INFO] 2021-02-12 16:47:46,129: topic[/two_ints] removing connection to http://ip-172-31-17-9:43152/
[rospy.internal][INFO] 2021-02-12 16:47:46,132: topic[/two_ints] removing connection to http://ip-172-31-17-9:42108/
[rospy.impl.masterslave][INFO] 2021-02-12 16:47:46,136: signal-2
[rospy.core][INFO] 2021-02-12 16:47:46,755: signal_shutdown [atexit]
[rospy.client][INFO] 2021-02-12 16:48:21,667: init_node, name[/solution], pid[28461]
[xmlrpc][INFO] 2021-02-12 16:48:21,668: XML-RPC server binding to 0.0.0.0:0
[xmlrpc][INFO] 2021-02-12 16:48:21,675: Started XML-RPC server [http://ip-172-31-17-9:38706/]
[rospy.init][INFO] 2021-02-12 16:48:21,676: ROS Slave URI: [http://ip-172-31-17-9:38706/]
[rospy.impl.masterslave][INFO] 2021-02-12 16:48:21,679: _ready: http://ip-172-31-17-9:38706/
[xmlrpc][INFO] 2021-02-12 16:48:21,691: xml rpc node: starting XML-RPC server
[rospy.registration][INFO] 2021-02-12 16:48:21,692: Registering with master node http://localhost:40963
[rospy.init][INFO] 2021-02-12 16:48:21,786: registered with master
[rospy.rosout][INFO] 2021-02-12 16:48:21,789: initializing /rosout core topic
[rospy.rosout][INFO] 2021-02-12 16:48:21,830: connected to core topic /rosout
[rospy.simtime][INFO] 2021-02-12 16:48:21,866: /use_sim_time is not set, will not subscribe to simulated time [/clock] topic
[rospy.internal][INFO] 2021-02-12 16:48:21,998: topic[/two_ints] adding connection to [http://ip-172-31-17-9:43152/], count 0
[rospy.internal][INFO] 2021-02-12 16:48:22,042: topic[/rosout] adding connection to [/rosout], count 0
[rosout][INFO] 2021-02-12 16:48:22,854: a: 14
b: 18
[rosout][INFO] 2021-02-12 16:48:22,883: 32
[rosout][INFO] 2021-02-12 16:48:22,983: 32
[rospy.internal][INFO] 2021-02-12 16:48:22,989: topic[/two_ints] adding connection to [http://ip-172-31-17-9:38706/], count 1
[rosout][WARNING] 2021-02-12 16:48:23,005: Could not process inbound connection: topic types do not match: [project1_solution/TwoInts] vs. [std_msgs/Int16]{'message_definition': 'int16 a\nint16 b', 'callerid': '/solution', 'tcp_nodelay': '0', 'md5sum': 'e01e889cb1a7965611513515df5899bf', 'topic': '/two_ints', 'type': 'project1_solution/TwoInts'}
[rospy.internal][ERROR] 2021-02-12 16:48:23,006: Unable to initiate TCP/IP socket to ip-172-31-17-9:36659 (http://ip-172-31-17-9:38706/): Traceback (most recent call last):
  File "/opt/ros/kinetic/lib/python2.7/dist-packages/rospy/impl/tcpros_base.py", line 557, in connect
    self.read_header()
  File "/opt/ros/kinetic/lib/python2.7/dist-packages/rospy/impl/tcpros_base.py", line 650, in read_header
    self._validate_header(read_ros_handshake_header(sock, self.read_buff, self.protocol.buff_size))
  File "/opt/ros/kinetic/lib/python2.7/dist-packages/rospy/impl/tcpros_base.py", line 593, in _validate_header
    raise TransportInitError("remote error reported: %s"%header['error'])
TransportInitError: remote error reported: topic types do not match: [project1_solution/TwoInts] vs. [std_msgs/Int16]

[rospy.internal][ERROR] 2021-02-12 16:48:23,027: unable to create subscriber transport: remote error reported: topic types do not match: [project1_solution/TwoInts] vs. [std_msgs/Int16].  Will try again in 0.5s
[rosout][INFO] 2021-02-12 16:48:23,083: 32
[rosout][INFO] 2021-02-12 16:48:23,183: 32
[rosout][INFO] 2021-02-12 16:48:23,283: 32
[rosout][INFO] 2021-02-12 16:48:23,383: 32
[rosout][INFO] 2021-02-12 16:48:23,483: 32
[rosout][INFO] 2021-02-12 16:48:23,583: 32
[rosout][INFO] 2021-02-12 16:48:23,683: 32
[rosout][INFO] 2021-02-12 16:48:23,783: 32
[rosout][INFO] 2021-02-12 16:48:23,883: 32
[rosout][INFO] 2021-02-12 16:48:23,983: 32
[rospy.internal][ERROR] 2021-02-12 16:48:24,042: Unable to initiate TCP/IP socket to ip-172-31-17-9:36659 (http://ip-172-31-17-9:38706/): Traceback (most recent call last):
  File "/opt/ros/kinetic/lib/python2.7/dist-packages/rospy/impl/tcpros_base.py", line 557, in connect
    self.read_header()
  File "/opt/ros/kinetic/lib/python2.7/dist-packages/rospy/impl/tcpros_base.py", line 650, in read_header
    self._validate_header(read_ros_handshake_header(sock, self.read_buff, self.protocol.buff_size))
  File "/opt/ros/kinetic/lib/python2.7/dist-packages/rospy/impl/tcpros_base.py", line 593, in _validate_header
    raise TransportInitError("remote error reported: %s"%header['error'])
TransportInitError: remote error reported: topic types do not match: [project1_solution/TwoInts] vs. [std_msgs/Int16]

[rosout][WARNING] 2021-02-12 16:48:24,042: Could not process inbound connection: topic types do not match: [project1_solution/TwoInts] vs. [std_msgs/Int16]{'message_definition': 'int16 a\nint16 b', 'callerid': '/solution', 'tcp_nodelay': '0', 'md5sum': 'e01e889cb1a7965611513515df5899bf', 'topic': '/two_ints', 'type': 'project1_solution/TwoInts'}
[rosout][INFO] 2021-02-12 16:48:24,083: 32
[rosout][INFO] 2021-02-12 16:48:24,183: 32
[rosout][INFO] 2021-02-12 16:48:24,283: 32
[rosout][INFO] 2021-02-12 16:48:24,383: 32
[rosout][INFO] 2021-02-12 16:48:24,483: 32
[rosout][INFO] 2021-02-12 16:48:24,586: 32
[rosout][INFO] 2021-02-12 16:48:24,683: 32
[rosout][INFO] 2021-02-12 16:48:24,783: 32
[rosout][INFO] 2021-02-12 16:48:24,883: 32
[rosout][INFO] 2021-02-12 16:48:24,983: 32
[rosout][WARNING] 2021-02-12 16:48:25,053: Could not process inbound connection: topic types do not match: [project1_solution/TwoInts] vs. [std_msgs/Int16]{'message_definition': 'int16 a\nint16 b', 'callerid': '/solution', 'tcp_nodelay': '0', 'md5sum': 'e01e889cb1a7965611513515df5899bf', 'topic': '/two_ints', 'type': 'project1_solution/TwoInts'}
[rospy.internal][ERROR] 2021-02-12 16:48:25,054: Unable to initiate TCP/IP socket to ip-172-31-17-9:36659 (http://ip-172-31-17-9:38706/): Traceback (most recent call last):
  File "/opt/ros/kinetic/lib/python2.7/dist-packages/rospy/impl/tcpros_base.py", line 557, in connect
    self.read_header()
  File "/opt/ros/kinetic/lib/python2.7/dist-packages/rospy/impl/tcpros_base.py", line 650, in read_header
    self._validate_header(read_ros_handshake_header(sock, self.read_buff, self.protocol.buff_size))
  File "/opt/ros/kinetic/lib/python2.7/dist-packages/rospy/impl/tcpros_base.py", line 593, in _validate_header
    raise TransportInitError("remote error reported: %s"%header['error'])
TransportInitError: remote error reported: topic types do not match: [project1_solution/TwoInts] vs. [std_msgs/Int16]

[rosout][INFO] 2021-02-12 16:48:25,083: 32
[rosout][INFO] 2021-02-12 16:48:25,183: 32
[rosout][INFO] 2021-02-12 16:48:25,283: 32
[rosout][INFO] 2021-02-12 16:48:25,383: 32
[rosout][INFO] 2021-02-12 16:48:25,483: 32
[rosout][INFO] 2021-02-12 16:48:25,583: 32
[rosout][INFO] 2021-02-12 16:48:25,683: 32
[rosout][INFO] 2021-02-12 16:48:25,783: 32
[rosout][INFO] 2021-02-12 16:48:25,883: 32
[rosout][INFO] 2021-02-12 16:48:25,983: 32
[rosout][INFO] 2021-02-12 16:48:26,083: 32
[rosout][INFO] 2021-02-12 16:48:26,183: 32
[rosout][INFO] 2021-02-12 16:48:26,283: 32
[rosout][INFO] 2021-02-12 16:48:26,383: 32
[rosout][INFO] 2021-02-12 16:48:26,483: 32
[rosout][INFO] 2021-02-12 16:48:26,583: 32
[rosout][INFO] 2021-02-12 16:48:26,683: 32
[rosout][INFO] 2021-02-12 16:48:26,783: 32
[rosout][INFO] 2021-02-12 16:48:26,883: 32
[rosout][INFO] 2021-02-12 16:48:26,983: 32
[rosout][WARNING] 2021-02-12 16:48:27,062: Could not process inbound connection: topic types do not match: [project1_solution/TwoInts] vs. [std_msgs/Int16]{'message_definition': 'int16 a\nint16 b', 'callerid': '/solution', 'tcp_nodelay': '0', 'md5sum': 'e01e889cb1a7965611513515df5899bf', 'topic': '/two_ints', 'type': 'project1_solution/TwoInts'}
[rospy.internal][ERROR] 2021-02-12 16:48:27,063: Unable to initiate TCP/IP socket to ip-172-31-17-9:36659 (http://ip-172-31-17-9:38706/): Traceback (most recent call last):
  File "/opt/ros/kinetic/lib/python2.7/dist-packages/rospy/impl/tcpros_base.py", line 557, in connect
    self.read_header()
  File "/opt/ros/kinetic/lib/python2.7/dist-packages/rospy/impl/tcpros_base.py", line 650, in read_header
    self._validate_header(read_ros_handshake_header(sock, self.read_buff, self.protocol.buff_size))
  File "/opt/ros/kinetic/lib/python2.7/dist-packages/rospy/impl/tcpros_base.py", line 593, in _validate_header
    raise TransportInitError("remote error reported: %s"%header['error'])
TransportInitError: remote error reported: topic types do not match: [project1_solution/TwoInts] vs. [std_msgs/Int16]

[rosout][INFO] 2021-02-12 16:48:27,083: 32
[rosout][INFO] 2021-02-12 16:48:27,183: 32
[rosout][INFO] 2021-02-12 16:48:27,283: 32
[rosout][INFO] 2021-02-12 16:48:27,383: 32
[rosout][INFO] 2021-02-12 16:48:27,483: 32
[rosout][INFO] 2021-02-12 16:48:27,583: 32
[rosout][INFO] 2021-02-12 16:48:27,683: 32
[rosout][INFO] 2021-02-12 16:48:27,783: 32
[rosout][INFO] 2021-02-12 16:48:27,883: 32
[rosout][INFO] 2021-02-12 16:48:27,983: 32
[rosout][INFO] 2021-02-12 16:48:28,083: 32
[rosout][INFO] 2021-02-12 16:48:28,183: 32
[rosout][INFO] 2021-02-12 16:48:28,283: 32
[rosout][INFO] 2021-02-12 16:48:28,383: 32
[rosout][INFO] 2021-02-12 16:48:28,483: 32
[rosout][INFO] 2021-02-12 16:48:28,583: 32
[rosout][INFO] 2021-02-12 16:48:28,683: 32
[rosout][INFO] 2021-02-12 16:48:28,783: 32
[rosout][INFO] 2021-02-12 16:48:28,883: 32
[rosout][INFO] 2021-02-12 16:48:28,983: 32
[rosout][INFO] 2021-02-12 16:48:29,083: 32
[rosout][INFO] 2021-02-12 16:48:29,183: 32
[rosout][INFO] 2021-02-12 16:48:29,283: 32
[rosout][INFO] 2021-02-12 16:48:29,383: 32
[rosout][INFO] 2021-02-12 16:48:29,483: 32
[rosout][INFO] 2021-02-12 16:48:29,583: 32
[rosout][INFO] 2021-02-12 16:48:29,683: 32
[rosout][INFO] 2021-02-12 16:48:29,783: 32
[rosout][INFO] 2021-02-12 16:48:29,883: 32
[rosout][INFO] 2021-02-12 16:48:29,983: 32
[rosout][INFO] 2021-02-12 16:48:30,083: 32
[rosout][INFO] 2021-02-12 16:48:30,183: 32
[rosout][INFO] 2021-02-12 16:48:30,283: 32
[rosout][INFO] 2021-02-12 16:48:30,383: 32
[rosout][INFO] 2021-02-12 16:48:30,483: 32
[rosout][INFO] 2021-02-12 16:48:30,583: 32
[rosout][INFO] 2021-02-12 16:48:30,683: 32
[rosout][INFO] 2021-02-12 16:48:30,783: 32
[rosout][INFO] 2021-02-12 16:48:30,883: 32
[rosout][INFO] 2021-02-12 16:48:30,983: 32
[rospy.internal][ERROR] 2021-02-12 16:48:31,080: Unable to initiate TCP/IP socket to ip-172-31-17-9:36659 (http://ip-172-31-17-9:38706/): Traceback (most recent call last):
  File "/opt/ros/kinetic/lib/python2.7/dist-packages/rospy/impl/tcpros_base.py", line 557, in connect
    self.read_header()
  File "/opt/ros/kinetic/lib/python2.7/dist-packages/rospy/impl/tcpros_base.py", line 650, in read_header
    self._validate_header(read_ros_handshake_header(sock, self.read_buff, self.protocol.buff_size))
  File "/opt/ros/kinetic/lib/python2.7/dist-packages/rospy/impl/tcpros_base.py", line 593, in _validate_header
    raise TransportInitError("remote error reported: %s"%header['error'])
TransportInitError: remote error reported: topic types do not match: [project1_solution/TwoInts] vs. [std_msgs/Int16]

[rosout][WARNING] 2021-02-12 16:48:31,080: Could not process inbound connection: topic types do not match: [project1_solution/TwoInts] vs. [std_msgs/Int16]{'message_definition': 'int16 a\nint16 b', 'callerid': '/solution', 'tcp_nodelay': '0', 'md5sum': 'e01e889cb1a7965611513515df5899bf', 'topic': '/two_ints', 'type': 'project1_solution/TwoInts'}
[rosout][INFO] 2021-02-12 16:48:31,083: 32
[rosout][INFO] 2021-02-12 16:48:31,183: 32
[rosout][INFO] 2021-02-12 16:48:31,283: 32
[rosout][INFO] 2021-02-12 16:48:31,383: 32
[rosout][INFO] 2021-02-12 16:48:31,483: 32
[rosout][INFO] 2021-02-12 16:48:31,583: 32
[rosout][INFO] 2021-02-12 16:48:31,683: 32
[rosout][INFO] 2021-02-12 16:48:31,783: 32
[rosout][INFO] 2021-02-12 16:48:31,883: 32
[rosout][INFO] 2021-02-12 16:48:31,983: 32
[rosout][INFO] 2021-02-12 16:48:32,085: 32
[rosout][INFO] 2021-02-12 16:48:32,183: 32
[rosout][INFO] 2021-02-12 16:48:32,283: 32
[rosout][INFO] 2021-02-12 16:48:32,383: 32
[rosout][INFO] 2021-02-12 16:48:32,483: 32
[rosout][INFO] 2021-02-12 16:48:32,583: 32
[rosout][INFO] 2021-02-12 16:48:32,683: 32
[rosout][INFO] 2021-02-12 16:48:32,783: 32
[rosout][INFO] 2021-02-12 16:48:32,883: 32
[rosout][INFO] 2021-02-12 16:48:32,983: 32
[rosout][INFO] 2021-02-12 16:48:33,083: 32
[rosout][INFO] 2021-02-12 16:48:33,183: 32
[rosout][INFO] 2021-02-12 16:48:33,283: 32
[rosout][INFO] 2021-02-12 16:48:33,383: 32
[rosout][INFO] 2021-02-12 16:48:33,483: 32
[rosout][INFO] 2021-02-12 16:48:33,583: 32
[rosout][INFO] 2021-02-12 16:48:33,683: 32
[rosout][INFO] 2021-02-12 16:48:33,783: 32
[rosout][INFO] 2021-02-12 16:48:33,883: 32
[rosout][INFO] 2021-02-12 16:48:33,983: 32
[rosout][INFO] 2021-02-12 16:48:34,083: 32
[rosout][INFO] 2021-02-12 16:48:34,183: 32
[rosout][INFO] 2021-02-12 16:48:34,283: 32
[rosout][INFO] 2021-02-12 16:48:34,383: 32
[rosout][INFO] 2021-02-12 16:48:34,483: 32
[rosout][INFO] 2021-02-12 16:48:34,583: 32
[rosout][INFO] 2021-02-12 16:48:34,683: 32
[rosout][INFO] 2021-02-12 16:48:34,783: 32
[rospy.client][INFO] 2021-02-12 16:49:24,173: init_node, name[/solution], pid[30849]
[xmlrpc][INFO] 2021-02-12 16:49:24,173: XML-RPC server binding to 0.0.0.0:0
[xmlrpc][INFO] 2021-02-12 16:49:24,178: Started XML-RPC server [http://ip-172-31-17-9:41972/]
[rospy.init][INFO] 2021-02-12 16:49:24,178: ROS Slave URI: [http://ip-172-31-17-9:41972/]
[rospy.impl.masterslave][INFO] 2021-02-12 16:49:24,184: _ready: http://ip-172-31-17-9:41972/
[xmlrpc][INFO] 2021-02-12 16:49:24,192: xml rpc node: starting XML-RPC server
[rospy.registration][INFO] 2021-02-12 16:49:24,192: Registering with master node http://localhost:40963
[rospy.init][INFO] 2021-02-12 16:49:24,288: registered with master
[rospy.rosout][INFO] 2021-02-12 16:49:24,292: initializing /rosout core topic
[rospy.rosout][INFO] 2021-02-12 16:49:24,299: connected to core topic /rosout
[rospy.simtime][INFO] 2021-02-12 16:49:24,305: /use_sim_time is not set, will not subscribe to simulated time [/clock] topic
[rospy.internal][INFO] 2021-02-12 16:49:24,364: topic[/two_ints] adding connection to [http://ip-172-31-17-9:43152/], count 0
[rospy.internal][INFO] 2021-02-12 16:49:24,563: topic[/rosout] adding connection to [/rosout], count 0
[rosout][INFO] 2021-02-12 16:49:24,856: a: 12
b: 20
[rosout][INFO] 2021-02-12 16:49:24,865: 32
[rospy.internal][INFO] 2021-02-12 16:49:24,875: topic[/two_ints] adding connection to [http://ip-172-31-17-9:41972/], count 1
[rosout][WARNING] 2021-02-12 16:49:24,879: Could not process inbound connection: topic types do not match: [project1_solution/TwoInts] vs. [std_msgs/Int16]{'message_definition': 'int16 a\nint16 b', 'callerid': '/solution', 'tcp_nodelay': '0', 'md5sum': 'e01e889cb1a7965611513515df5899bf', 'topic': '/two_ints', 'type': 'project1_solution/TwoInts'}
[rospy.internal][ERROR] 2021-02-12 16:49:24,879: Unable to initiate TCP/IP socket to ip-172-31-17-9:37535 (http://ip-172-31-17-9:41972/): Traceback (most recent call last):
  File "/opt/ros/kinetic/lib/python2.7/dist-packages/rospy/impl/tcpros_base.py", line 557, in connect
    self.read_header()
  File "/opt/ros/kinetic/lib/python2.7/dist-packages/rospy/impl/tcpros_base.py", line 650, in read_header
    self._validate_header(read_ros_handshake_header(sock, self.read_buff, self.protocol.buff_size))
  File "/opt/ros/kinetic/lib/python2.7/dist-packages/rospy/impl/tcpros_base.py", line 593, in _validate_header
    raise TransportInitError("remote error reported: %s"%header['error'])
TransportInitError: remote error reported: topic types do not match: [project1_solution/TwoInts] vs. [std_msgs/Int16]

[rospy.internal][ERROR] 2021-02-12 16:49:24,886: unable to create subscriber transport: remote error reported: topic types do not match: [project1_solution/TwoInts] vs. [std_msgs/Int16].  Will try again in 0.5s
[rosout][WARNING] 2021-02-12 16:49:25,892: Could not process inbound connection: topic types do not match: [project1_solution/TwoInts] vs. [std_msgs/Int16]{'message_definition': 'int16 a\nint16 b', 'callerid': '/solution', 'tcp_nodelay': '0', 'md5sum': 'e01e889cb1a7965611513515df5899bf', 'topic': '/two_ints', 'type': 'project1_solution/TwoInts'}
[rospy.internal][ERROR] 2021-02-12 16:49:25,893: Unable to initiate TCP/IP socket to ip-172-31-17-9:37535 (http://ip-172-31-17-9:41972/): Traceback (most recent call last):
  File "/opt/ros/kinetic/lib/python2.7/dist-packages/rospy/impl/tcpros_base.py", line 557, in connect
    self.read_header()
  File "/opt/ros/kinetic/lib/python2.7/dist-packages/rospy/impl/tcpros_base.py", line 650, in read_header
    self._validate_header(read_ros_handshake_header(sock, self.read_buff, self.protocol.buff_size))
  File "/opt/ros/kinetic/lib/python2.7/dist-packages/rospy/impl/tcpros_base.py", line 593, in _validate_header
    raise TransportInitError("remote error reported: %s"%header['error'])
TransportInitError: remote error reported: topic types do not match: [project1_solution/TwoInts] vs. [std_msgs/Int16]

[rosout][INFO] 2021-02-12 16:49:26,856: a: 9
b: 4
[rosout][INFO] 2021-02-12 16:49:26,860: 13
[rospy.internal][ERROR] 2021-02-12 16:49:26,902: Unable to initiate TCP/IP socket to ip-172-31-17-9:37535 (http://ip-172-31-17-9:41972/): Traceback (most recent call last):
  File "/opt/ros/kinetic/lib/python2.7/dist-packages/rospy/impl/tcpros_base.py", line 557, in connect
    self.read_header()
  File "/opt/ros/kinetic/lib/python2.7/dist-packages/rospy/impl/tcpros_base.py", line 650, in read_header
    self._validate_header(read_ros_handshake_header(sock, self.read_buff, self.protocol.buff_size))
  File "/opt/ros/kinetic/lib/python2.7/dist-packages/rospy/impl/tcpros_base.py", line 593, in _validate_header
    raise TransportInitError("remote error reported: %s"%header['error'])
TransportInitError: remote error reported: topic types do not match: [project1_solution/TwoInts] vs. [std_msgs/Int16]

[rosout][WARNING] 2021-02-12 16:49:26,902: Could not process inbound connection: topic types do not match: [project1_solution/TwoInts] vs. [std_msgs/Int16]{'message_definition': 'int16 a\nint16 b', 'callerid': '/solution', 'tcp_nodelay': '0', 'md5sum': 'e01e889cb1a7965611513515df5899bf', 'topic': '/two_ints', 'type': 'project1_solution/TwoInts'}
[rosout][INFO] 2021-02-12 16:49:28,856: a: 20
b: 16
[rosout][INFO] 2021-02-12 16:49:28,860: 36
[rospy.internal][ERROR] 2021-02-12 16:49:28,907: Unable to initiate TCP/IP socket to ip-172-31-17-9:37535 (http://ip-172-31-17-9:41972/): Traceback (most recent call last):
  File "/opt/ros/kinetic/lib/python2.7/dist-packages/rospy/impl/tcpros_base.py", line 557, in connect
    self.read_header()
  File "/opt/ros/kinetic/lib/python2.7/dist-packages/rospy/impl/tcpros_base.py", line 650, in read_header
    self._validate_header(read_ros_handshake_header(sock, self.read_buff, self.protocol.buff_size))
  File "/opt/ros/kinetic/lib/python2.7/dist-packages/rospy/impl/tcpros_base.py", line 593, in _validate_header
    raise TransportInitError("remote error reported: %s"%header['error'])
TransportInitError: remote error reported: topic types do not match: [project1_solution/TwoInts] vs. [std_msgs/Int16]

[rosout][WARNING] 2021-02-12 16:49:28,907: Could not process inbound connection: topic types do not match: [project1_solution/TwoInts] vs. [std_msgs/Int16]{'message_definition': 'int16 a\nint16 b', 'callerid': '/solution', 'tcp_nodelay': '0', 'md5sum': 'e01e889cb1a7965611513515df5899bf', 'topic': '/two_ints', 'type': 'project1_solution/TwoInts'}
[rosout][INFO] 2021-02-12 16:49:30,856: a: 3
b: 2
[rosout][INFO] 2021-02-12 16:49:30,860: 5
[rosout][INFO] 2021-02-12 16:49:32,856: a: 15
b: 20
[rosout][INFO] 2021-02-12 16:49:32,860: 35
[rospy.internal][ERROR] 2021-02-12 16:49:32,914: Unable to initiate TCP/IP socket to ip-172-31-17-9:37535 (http://ip-172-31-17-9:41972/): Traceback (most recent call last):
  File "/opt/ros/kinetic/lib/python2.7/dist-packages/rospy/impl/tcpros_base.py", line 557, in connect
    self.read_header()
  File "/opt/ros/kinetic/lib/python2.7/dist-packages/rospy/impl/tcpros_base.py", line 650, in read_header
    self._validate_header(read_ros_handshake_header(sock, self.read_buff, self.protocol.buff_size))
  File "/opt/ros/kinetic/lib/python2.7/dist-packages/rospy/impl/tcpros_base.py", line 593, in _validate_header
    raise TransportInitError("remote error reported: %s"%header['error'])
TransportInitError: remote error reported: topic types do not match: [project1_solution/TwoInts] vs. [std_msgs/Int16]

[rosout][WARNING] 2021-02-12 16:49:32,914: Could not process inbound connection: topic types do not match: [project1_solution/TwoInts] vs. [std_msgs/Int16]{'message_definition': 'int16 a\nint16 b', 'callerid': '/solution', 'tcp_nodelay': '0', 'md5sum': 'e01e889cb1a7965611513515df5899bf', 'topic': '/two_ints', 'type': 'project1_solution/TwoInts'}
[rosout][INFO] 2021-02-12 16:49:34,854: a: 11
b: 10
[rosout][INFO] 2021-02-12 16:49:34,858: 21
[rosout][INFO] 2021-02-12 16:49:36,856: a: 16
b: 4
[rosout][INFO] 2021-02-12 16:49:36,860: 20
[rospy.core][INFO] 2021-02-12 16:49:37,645: signal_shutdown [signal-2]
[rospy.internal][INFO] 2021-02-12 16:49:37,672: topic[/rosout] removing connection to /rosout
[rospy.internal][INFO] 2021-02-12 16:49:37,676: topic[/two_ints] removing connection to http://ip-172-31-17-9:43152/
[rospy.internal][WARNING] 2021-02-12 16:49:37,677: Unknown error initiating TCP/IP socket to ip-172-31-17-9:46199 (http://ip-172-31-17-9:43152/): Traceback (most recent call last):
  File "/opt/ros/kinetic/lib/python2.7/dist-packages/rospy/impl/tcpros_base.py", line 557, in connect
    self.read_header()
  File "/opt/ros/kinetic/lib/python2.7/dist-packages/rospy/impl/tcpros_base.py", line 650, in read_header
    self._validate_header(read_ros_handshake_header(sock, self.read_buff, self.protocol.buff_size))
AttributeError: 'NoneType' object has no attribute 'buff_size'

[rospy.topics][ERROR] 2021-02-12 16:49:37,681: Traceback (most recent call last):
  File "/opt/ros/kinetic/lib/python2.7/dist-packages/rospy/topics.py", line 326, in close
    c.close()
  File "/opt/ros/kinetic/lib/python2.7/dist-packages/rospy/impl/tcpros_base.py", line 838, in close
    self.socket.close()
AttributeError: 'NoneType' object has no attribute 'close'

[rospy.internal][INFO] 2021-02-12 16:49:37,689: topic[/two_ints] removing connection to http://ip-172-31-17-9:41972/
[rospy.impl.masterslave][INFO] 2021-02-12 16:49:37,692: signal-2
[rospy.core][INFO] 2021-02-12 16:49:37,796: signal_shutdown [atexit]
[rospy.impl.masterslave][INFO] 2021-02-12 21:28:47,125: external shutdown request from [/master]: new node registered with same name
[rospy.core][INFO] 2021-02-12 21:28:47,126: signal_shutdown [external shutdown request from [/master]: [new node registered with same name]]
[rospy.registration][WARNING] 2021-02-12 21:28:47,133: cannot unregister with master due to network issues
[rospy.internal][INFO] 2021-02-12 21:28:47,139: topic[/rosout] removing connection to /rosout
[rospy.internal][INFO] 2021-02-12 21:28:47,142: topic[/two_ints] removing connection to http://ip-172-31-17-9:43152/
[rospy.internal][INFO] 2021-02-12 21:28:47,146: topic[/two_ints] removing connection to http://ip-172-31-17-9:38706/
[rospy.core][INFO] 2021-02-12 21:28:47,210: signal_shutdown [signal-15]
[rospy.core][INFO] 2021-02-12 21:28:47,288: signal_shutdown [atexit]
